Workbook

Sheet 1. Giả định & Thông số
A1: GIẢ ĐỊNH & THÔNG SỐ DỰ ÁN - CHAMP MẠNH CHAT
A2: Chỉ tiêu | B2: Giá trị | C2: Đơn vị | D2: Ghi chú
A3: A. ĐẦU TƯ BAN ĐẦU
A4: Chi phí thành lập doanh nghiệp | B4: 10 | C4: Triệu VND | D4: Thực tế: đăng ký, con dấu, pháp lý 2024-2025
A5: Chi phí phát triển ứng dụng | B5: 1800 | C5: Triệu VND | D5: MVP mobile app + AI cơ bản + API BH/NH - outsource VN ~$70-85k; phát triển theo giai đoạn
A6: chi phí cho nhân sự trước khởi nghiệp | B6: ='3. Chi phí chi tiết'!B10 -> 444 | C6: Triệu VND
A7: Chi phí ra mắt sản phẩm / triển khai | B7: 900 | C7: Triệu VND | D7: Pilot B2B tập trung: webinar online + onboarding digital (giảm chi phí thuê hội trường)
A8: → TỔNG ĐẦU TƯ BAN ĐẦU | B8: =B4+B5+B6+B7 -> 3154 | C8: Triệu VND | D8: Cập nhật theo giả định thực tế
A9: B. CẤU TRÚC VỐN
A10: Tỷ trọng vốn vay (D/V) | B10: 0.4 | C10: Tỷ lệ
A11: Tỷ trọng vốn chủ sở hữu (E/V) | B11: 0.6 | C11: Tỷ lệ
A12: Vốn vay (Debt) | B12: =B8*B10 -> 1261.6 | C12: Triệu VND
A13: Vốn chủ sở hữu (Equity) | B13: =B8*B11 -> 1892.4 | C13: Triệu VND
A14: Lãi suất vay (Rd) | B14: 0.11 | C14: Năm
A15: Chi phí vốn chủ (Re) | B15: 0.18 | C15: Năm
A16: Thuế TNDN (T) | B16: 0.2 | C16: Tỷ lệ
A17: WACC | B17: =B15*B11+B14*(1-B16)*B10 -> 0.1432 | C17: Năm | D17: Re×E/V + Rd×(1-T)×D/V | Cập nhật theo cấu trúc vốn mới
A18: Số kỳ vay / hoàn vốn | B18: 4 | C18: Năm | D18: Thời hạn vay
A19: C. NHÂN SỰ & LƯƠNG
A20: Chỉ tiêu | B20: N0 | C20: N1 | D20: N2 | E20: N3 | F20: N4 | G20: N5 | H20: N6 | I20: N7 | J20: Lương cơ bản (tr/th)
A21: Giám đốc điều hành | B21: 1 | C21: 1 | D21: 1 | E21: 1 | F21: 2 | G21: 2 | H21: 2 | I21: 2 | J21: 10
A22: Nhân sự IT/Kỹ thuật | B22: 1 | C22: 2 | D22: 2 | E22: 3 | F22: 4 | G22: 4 | H22: 4 | I22: 4 | J22: 8
A23: Nhân sự vận hành hệ thống | B23: 1 | C23: 1 | D23: 1 | E23: 1 | F23: 2 | G23: 2 | H23: 2 | I23: 2 | J23: 7
A24: Nhân sự Marketing | B24: 1 | C24: 1 | D24: 1 | E24: 2 | F24: 2 | G24: 3 | H24: 3 | I24: 3 | J24: 6
A25: Nhân sự Finance/Kế toán | B25: 1 | C25: 1 | D25: 1 | E25: 1 | F25: 2 | G25: 2 | H25: 3 | I25: 3 | J25: 6
A26: Nhân sự chăm sóc khách hàng | B26: 0 | C26: 1 | D26: 2 | E26: 2 | F26: 2 | G26: 2 | H26: 3 | I26: 3 | J26: 7
A27: Tỷ lệ tăng lương hàng năm | B27: 0.05 | C27: Năm
A28: D. GIẢ ĐỊNH DOANH THU
A29: Số doanh nghiệp đối tác (N1/N2/N3/N4/N5) | B29: 8/15/25/40/60 | C29: DN
A30: Phí sử dụng app / DN / tháng | B30: 13 | C30: Triệu VND
A31: Tỷ lệ hoa hồng bảo hiểm | B31: 0.15 | C31: Tỷ lệ | D31: Hoa hồng đại lý BH nông nghiệp VN thực tế: 10-20%, dùng 15%
A32: Tỷ lệ giá trị giao dịch từ DN (trả trước) | B32: 0.05 | C32: Tỷ lệ
A33: Tỷ lệ giá trị giao dịch từ DN (trả sau) | B33: 0.0595 | C33: Tỷ lệ
A34: E. GIẢ ĐỊNH VỐN LƯU ĐỘNG
A35: Khoản phải thu (AR) / Doanh thu | B35: 0.1 | C35: Tỷ lệ | D35: 10% DT chưa thu được
A36: Khoản phải trả (AP) / Chi phí vận hành | B36: 0.1 | C36: Tỷ lệ | D36: 10% CP chưa thanh toán
A37: Số dư tiền mặt tối thiểu (CB) / Doanh thu | B37: 0.02 | C37: Tỷ lệ | D37: 2% DT dự phòng
A38: F. TỶ LỆ CHI PHÍ HOẠT ĐỘNG / DOANH THU
A39: Chi phí hoạt động nền tảng | B39: 0.2 | C39: Tỷ lệ DT | D39: - server, API, cloud; tối ưu hóa cloud cost bằng contract dài hạn AWS/GCP
A40: Chi phí Marketing | B40: 0.12 | C40: Tỷ lệ DT | D40: 12% DT - tập trung B2B partnership thay vì paid ads; CAC thấp hơn nhờ referral
...

Sheet 2. Báo cáo Ngân lưu
A1: BÁO CÁO NGÂN LƯU DỰ ÁN - CHAMP MẠNH CHAT (Đơn vị: Triệu VND)
A3: KHOẢN MỤC | B3: Năm 0 (Đầu tư) | C3: Năm 1 | D3: Năm 2 | E3: Năm 3 | F3: Năm 4 | G3: Năm 5 | H3: Năm 6 | I3: Năm 7
A4: I. NGÂN LƯU VÀO (INFLOWS)
A5: 1. Doanh thu phí sử dụng app (từ doanh nghiệp) | B5: - | C5: =C6*C7*12 -> 2340 | D5: =D6*D7*12 -> 3120 | E5: =E6*E7*12 -> 4680 | F5: =F6*F7*12 -> 6240 | G5: =G6*G7*12 -> 7020 | H5: =H6*H7*12 -> 7800 | I5: =I6*I7*12 -> 8580
A6: → Số DN đối tác | B6: - | C6: 15 | D6: 20 | E6: 30 | F6: 40 | G6: 45 | H6: 50 | I6: 55
A7: → Phí/DN/tháng (triệu) | B7: - | C7: ='1. Giả định & Thông số'!$B$30 -> 13 | D7: ='1. Giả định & Thông số'!$B$30 -> 13 | E7: ='1. Giả định & Thông số'!$B$30 -> 13 | F7: ='1. Giả định & Thông số'!$B$30 -> 13 | G7: ='1. Giả định & Thông số'!$B$30 -> 13 | H7: ='1. Giả định & Thông số'!$B$30 -> 13 | I7: ='1. Giả định & Thông số'!$B$30 -> 13
A8: 2. Doanh thu hoa hồng - Bảo hiểm nông nghiệp | B8: - | J8: Dự kiến
A9: → Doanh thu bán bảo hiểm | B9: - | J9: Dự kiến
A10: → Tỷ lệ hoa hồng BH | B10: - | J10: Dự kiến
A11: 3. Doanh thu hoa hồng - Doanh nghiệp & Ngân hàng | B11: - | C11: =C12*5%+C13*6% -> 210 | D11: =D12*5%+D13*6% -> 358.4 | E11: =E12*5%+E13*6% -> 705.6 | F11: =F12*5%+F13*6% -> 1232 | G11: =G12*5%+G13*6% -> 1764 | H11: =H12*5%+H13*6% -> 2100 | I11: =I12*5%+I13*6% -> 2425.5
A12: → Giá trị giao dịch trả trước qua nền tảng (5%) | B12: - | C12: ='1. Giả định & Thông số'!$B$56*C6*'1. Giả định & Thông số'!B58 -> 1500 | D12: ='1. Giả định & Thông số'!$B$56*D6*'1. Giả định & Thông số'!C58 -> 2560 | E12: ='1. Giả định & Thông số'!$B$56*E6*'1. Giả định & Thông số'!D58 -> 5040 | F12: ='1. Giả định & Thông số'!$B$56*F6*'1. Giả định & Thông số'!E58 -> 8800 | G12: ='1. Giả định & Thông số'!$B$56*G6*'1. Giả định & Thông số'!F58 -> 12600 | H12: ='1. Giả định & Thông số'!$B$56*H6*'1. Giả định & Thông số'!G58 -> 15000 | I12: ='1. Giả định & Thông số'!$B$56*I6*'1. Giả định & Thông số'!H58 -> 17325
A13: → Giá trị giao dịch trả sau qua nền tảng (6%) | B13: - | C13: =C12*'1. Giả định & Thông số'!$B$59 -> 2250 | D13: =D12*'1. Giả định & Thông số'!$B$59 -> 3840 | E13: =E12*'1. Giả định & Thông số'!$B$59 -> 7560 | F13: =F12*'1. Giả định & Thông số'!$B$59 -> 13200 | G13: =G12*'1. Giả định & Thông số'!$B$59 -> 18900 | H13: =H12*'1. Giả định & Thông số'!$B$59 -> 22500 | I13: =I12*'1. Giả định & Thông số'!$B$59 -> 25987.5
A14: 4. Thu hồi vốn lưu động (cuối dự án - năm 7) | B14: 0 | C14: 0 | D14: 0 | E14: 0 | F14: 0 | G14: ='1. Giả định & Thông số'!$B$35*(G5+G8+G11) -> 878.4 | H14: ='1. Giả định & Thông số'!$B$35*(H5+H8+H11) -> 990 | I14: ='1. Giả định & Thông số'!$B$35*(I5+I8+I11) -> 1100.55
A15: TỔNG NGÂN LƯU VÀO | B15: 0 | C15: =C5+C8+C11+IF(ISNUMBER(C14),C14,0) -> 2550 | D15: =D5+D8+D11+IF(ISNUMBER(D14),D14,0) -> 3478.4 | E15: =E5+E8+E11+IF(ISNUMBER(E14),E14,0) -> 5385.6 | F15: =F5+F8+F11+IF(ISNUMBER(F14),F14,0) -> 7472 | G15: =G5+G8+G11+IF(ISNUMBER(G14),G14,0) -> 9662.4 | H15: =H5+H8+H11+IF(ISNUMBER(H14),H14,0) -> 10890 | I15: =I5+I8+I11+IF(ISNUMBER(I14),I14,0) -> 12106.05
A17: II. NGÂN LƯU RA (OUTFLOWS)
A18: A. Chi phí đầu tư ban đầu (năm 0) | B18: ='1. Giả định & Thông số'!B8 -> 3154 | C18: - | D18: - | E18: - | F18: - | G18: - | H18: - | I18: -
A19: → Chi phí thành lập DN | B19: ='1. Giả định & Thông số'!$B$4 -> 10 | C19: - | D19: - | E19: - | F19: - | G19: - | H19: - | I19: -
A20: chi phí nhân sự trước khởi nghiệp | B20: ='3. Chi phí chi tiết'!B10 -> 444
A21: → Chi phí phát triển ứng dụng | B21: ='1. Giả định & Thông số'!$B$5 -> 1800 | C21: - | D21: - | E21: - | F21: - | G21: - | H21: - | I21: -
A22: → Chi phí vật tư, thiết bị | C22: - | D22: - | E22: - | F22: - | G22: - | H22: - | I22: -
A23: → Chi phí triển khai & ra mắt sản phẩm | B23: ='1. Giả định & Thông số'!$B$7 -> 900 | C23: - | D23: - | E23: - | F23: - | G23: - | H23: - | I23: -
A24: B. Chi phí nhân sự (tăng lương 5%/năm) | B24: - | C24: ='3. Chi phí chi tiết'!C10 -> 624 | D24: ='3. Chi phí chi tiết'!D10 -> 743.4 | E24: ='3. Chi phí chi tiết'!E10 -> 965.79 | F24: ='3. Chi phí chi tiết'!F10 -> 1444.716 | G24: ='3. Chi phí chi tiết'!G10 -> 1604.4682 | H24: ='3. Chi phí chi tiết'!H10 -> 1883.7916 | I24: ='3. Chi phí chi tiết'!I10 -> 1977.9812
A25: → Giám đốc điều hành | B25: - | C25: ='3. Chi phí chi tiết'!C4 -> 120 | D25: ='3. Chi phí chi tiết'!D4 -> 126 | E25: ='3. Chi phí chi tiết'!E4 -> 132.3 | F25: ='3. Chi phí chi tiết'!F4 -> 277.83 | G25: ='3. Chi phí chi tiết'!G4 -> 291.7215 | H25: ='3. Chi phí chi tiết'!H4 -> 306.30757 | I25: ='3. Chi phí chi tiết'!I4 -> 321.62295
A26: → Nhân sự IT/Kỹ thuật (×2) | B26: - | C26: ='3. Chi phí chi tiết'!C5 -> 192 | D26: ='3. Chi phí chi tiết'!D5 -> 201.6 | E26: ='3. Chi phí chi tiết'!E5 -> 317.52 | F26: ='3. Chi phí chi tiết'!F5 -> 444.528 | G26: ='3. Chi phí chi tiết'!G5 -> 466.7544 | H26: ='3. Chi phí chi tiết'!H5 -> 490.09212 | I26: ='3. Chi phí chi tiết'!I5 -> 514.59673
A27: → Nhân sự vận hành, Marketing, Finance, CSKH | B27: - | C27: =SUM('3. Chi phí chi tiết'!C6:C9) -> 312 | D27: =SUM('3. Chi phí chi tiết'!D6:D9) -> 415.8 | E27: =SUM('3. Chi phí chi tiết'!E6:E9) -> 515.97 | F27: =SUM('3. Chi phí chi tiết'!F6:F9) -> 722.358 | G27: =SUM('3. Chi phí chi tiết'!G6:G9) -> 845.99235 | H27: =SUM('3. Chi phí chi tiết'!H6:H9) -> 1087.3919 | I27: =SUM('3. Chi phí chi tiết'!I6:I9) -> 1141.7615
A28: C. Chi phí duy trì công nghệ (15% CP app / năm) | B28: - | C28: ='3. Chi phí chi tiết'!C13 -> 270 | D28: ='3. Chi phí chi tiết'!D13 -> 270 | E28: ='3. Chi phí chi tiết'!E13 -> 270 | F28: ='3. Chi phí chi tiết'!F13 -> 270 | G28: ='3. Chi phí chi tiết'!G13 -> 270 | H28: ='3. Chi phí chi tiết'!H13 -> 270 | I28: ='3. Chi phí chi tiết'!I13 -> 270
A29: D. Chi phí hoạt động nền tảng (15% DT) | B29: - | C29: ='3. Chi phí chi tiết'!C14 -> 510 | D29: ='3. Chi phí chi tiết'!D14 -> 695.68 | E29: ='3. Chi phí chi tiết'!E14 -> 1077.12 | F29: ='3. Chi phí chi tiết'!F14 -> 1494.4 | G29: ='3. Chi phí chi tiết'!G14 -> 1932.48 | H29: ='3. Chi phí chi tiết'!H14 -> 2178 | I29: ='3. Chi phí chi tiết'!I14 -> 2421.21
A30: E. Chi phí Marketing (15% DT) | B30: - | C30: ='3. Chi phí chi tiết'!C18 -> 306 | D30: ='3. Chi phí chi tiết'!D18 -> 417.408 | E30: ='3. Chi phí chi tiết'!E18 -> 646.272 | F30: ='3. Chi phí chi tiết'!F18 -> 896.64 | G30: ='3. Chi phí chi tiết'!G18 -> 1159.488 | H30: ='3. Chi phí chi tiết'!H18 -> 1306.8 | I30: ='3. Chi phí chi tiết'!I18 -> 1452.726
A31: F. Chi phí Quản lý & Hành chính (cố định) | B31: - | C31: ='1. Giả định & Thông số'!$B$43 -> 240 | D31: ='1. Giả định & Thông số'!$B$43 -> 240 | E31: ='1. Giả định & Thông số'!$B$43 -> 240 | F31: ='1. Giả định & Thông số'!$B$43 -> 240 | G31: ='1. Giả định & Thông số'!$B$43 -> 240 | H31: ='1. Giả định & Thông số'!$B$43 -> 240 | I31: ='1. Giả định & Thông số'!$B$43 -> 240
A32: G. Chi phí Tài chính & Pháp lý định kỳ | B32: - | C32: ='1. Giả định & Thông số'!$B$44 -> 30 | D32: ='1. Giả định & Thông số'!$B$44 -> 30 | E32: ='1. Giả định & Thông số'!$B$44 -> 30 | F32: ='1. Giả định & Thông số'!$B$44 -> 30 | G32: ='1. Giả định & Thông số'!$B$44 -> 30 | H32: ='1. Giả định & Thông số'!$B$44 -> 30 | I32: ='1. Giả định & Thông số'!$B$44 -> 30
A33: H. Chi phí R&D (12% DT) | B33: - | C33: ='3. Chi phí chi tiết'!C19 -> 255 | D33: ='3. Chi phí chi tiết'!D19 -> 347.84 | E33: ='3. Chi phí chi tiết'!E19 -> 538.56 | F33: ='3. Chi phí chi tiết'!F19 -> 747.2 | G33: ='3. Chi phí chi tiết'!G19 -> 966.24 | H33: ='3. Chi phí chi tiết'!H19 -> 1089 | I33: ='3. Chi phí chi tiết'!I19 -> 1210.605
A34: I. Tăng vốn lưu động thuần (ΔNWC) | B34: - | C34: =MAX(0,'1. Giả định & Thông số'!$B$35*C15) -> 255 | D34: =MAX(0,'1. Giả định & Thông số'!$B$35*(D15-C15)) -> 92.84 | E34: =MAX(0,'1. Giả định & Thông số'!$B$35*(E15-D15)) -> 190.72 | F34: =MAX(0,'1. Giả định & Thông số'!$B$35*(F15-E15)) -> 208.64 | G34: =MAX(0,'1. Giả định & Thông số'!$B$35*(G15-F15)) -> 219.04 | H34: =MAX(0,'1. Giả định & Thông số'!$B$35*(H15-G15)) -> 122.76 | I34: =MAX(0,'1. Giả định & Thông số'!$B$35*(I15-H15)) -> 121.605
A35: → ΔAR (khoản phải thu tăng thêm) | B35: - | C35: =MAX(0,'1. Giả định & Thông số'!$B$35*C15) -> 255 | D35: =MAX(0,'1. Giả định & Thông số'!$B$35*(D15-C15)) -> 92.84 | E35: =MAX(0,'1. Giả định & Thông số'!$B$35*(E15-D15)) -> 190.72 | F35: =MAX(0,'1. Giả định & Thông số'!$B$35*(F15-E15)) -> 208.64 | G35: =MAX(0,'1. Giả định & Thông số'!$B$35*(G15-F15)) -> 219.04 | H35: =MAX(0,'1. Giả định & Thông số'!$B$35*(H15-G15)) -> 122.76 | I35: =MAX(0,'1. Giả định & Thông số'!$B$35*(I15-H15)) -> 121.605
A36: J. Thuế TNDN (20% lợi nhuận chịu thuế) | B36: - | C36: =MAX(0,'1. Giả định & Thông số'!$B$16*'4. Báo cáo Thu nhập'!C11) -> 0 | D36: =MAX(0,'1. Giả định & Thông số'!$B$16*'4. Báo cáo Thu nhập'!D11) -> 0.83807448 | E36: =MAX(0,'1. Giả định & Thông số'!$B$16*'4. Báo cáo Thu nhập'!E11) -> 184.13668 | F36: =MAX(0,'1. Giả định & Thông số'!$B$16*'4. Báo cáo Thu nhập'!F11) -> 397.63485 | G36: =MAX(0,'1. Giả định & Thông số'!$B$16*'4. Báo cáo Thu nhập'!G11) -> 627.83046 | H36: =MAX(0,'1. Giả định & Thông số'!$B$16*'4. Báo cáo Thu nhập'!H11) -> 727.05311 | I36: =MAX(0,'1. Giả định & Thông số'!$B$16*'4. Báo cáo Thu nhập'!I11) -> 849.277
A37: TỔNG NGÂN LƯU RA | B37: ='1. Giả định & Thông số'!$B$4+'1. Giả định & Thông số'!$B$5+'1. Giả định & Thông số'!$B$6+'1. Giả định & Thông số'!$B$7 -> 3154 | C37: =sum(C24,C28:C34,C36) -> 2490 | D37: =sum(D24,D28:D34,D36) -> 2838.0061 | E37: =sum(E24,E28:E34,E36) -> 4142.5987 | F37: =sum(F24,F28:F34,F36) -> 5729.2308 | G37: =sum(G24,G28:G34,G36) -> 7049.5467 | H37: =sum(H24,H28:H34,H36) -> 7847.4047 | I37: =sum(I24,I28:I34,I36) -> 8573.4042
A39: III. NGÂN LƯU RÒNG TRƯỚC TÀI TRỢ (NCF - TIPV)
A40: Ngân lưu ròng TIPV (= Inflow − Outflow) | B40: =-B37 -> -3154 | C40: =C15-C37 -> 60 | D40: =D15-D37 -> 640.39392 | E40: =E15-E37 -> 1243.0013 | F40: =F15-F37 -> 1742.7692 | G40: =G15-G37 -> 2612.8533 | H40: =H15-H37 -> 3042.5953 | I40: =I15-I37 -> 3532.6458
A41: Ngân lưu ròng TIPV lũy kế | B41: =B40 -> -3154 | C41: =sum(B41,C40) -> -3094 | D41: =sum(C41,D40) -> -2453.6061 | E41: =sum(D41,E40) -> -1210.6048 | F41: =sum(E41,F40) -> 532.1644 | G41: =sum(F41,G40) -> 3145.0177 | H41: =sum(G41,H40) -> 6187.613 | I41: =sum(H41,I40) -> 9720.2588
A43: IV. TÀI TRỢ VỐN VAY & LỊCH TRẢ NỢ
A44: Giải ngân vốn vay (năm 0) | B44: ='1. Giả định & Thông số'!$B$12 -> 1261.6 | C44: - | D44: - | E44: - | F44: - | G44: - | H44: - | I44: -
...

Sheet 3. Chi phí chi tiết
A1: BẢNG CHI PHÍ VẬN HÀNH CHI TIẾT - CHAMP MẠNH CHAT (Đơn vị: Triệu VND)
A2: KHOẢN MỤC | B2: Năm 0 (Đầu tư) | C2: Năm 1 | D2: Năm 2 | E2: Năm 3 | F2: Năm 4 | G2: Năm 5 | H2: Năm 6 | I2: Năm 7
A3: I. CHI PHÍ NHÂN SỰ
A4: Giám đốc điều hành | B4: ='1. Giả định & Thông số'!B21*'1. Giả định & Thông số'!$J$21*12 -> 120 | C4: ='1. Giả định & Thông số'!$C$21*'1. Giả định & Thông số'!$J$21*12*(1+'1. Giả định & Thông số'!$B$27)^0 -> 120 | D4: ='1. Giả định & Thông số'!$D$21*'1. Giả định & Thông số'!$J$21*12*(1+'1. Giả định & Thông số'!$B$27)^1 -> 126 | E4: ='1. Giả định & Thông số'!$E$21*'1. Giả định & Thông số'!$J$21*12*(1+'1. Giả định & Thông số'!$B$27)^2 -> 132.3 | F4: ='1. Giả định & Thông số'!$F$21*'1. Giả định & Thông số'!$J$21*12*(1+'1. Giả định & Thông số'!$B$27)^3 -> 277.83 | G4: ='1. Giả định & Thông số'!$G$21*'1. Giả định & Thông số'!$J$21*12*(1+'1. Giả định & Thông số'!$B$27)^4 -> 291.7215 | H4: ='1. Giả định & Thông số'!$H$21*'1. Giả định & Thông số'!$J$21*12*(1+'1. Giả định & Thông số'!$B$27)^5 -> 306.30757 | I4: ='1. Giả định & Thông số'!$G$21*'1. Giả định & Thông số'!$J$21*12*(1+'1. Giả định & Thông số'!$B$27)^6 -> 321.62295
A5: Nhân sự IT/Kỹ thuật | B5: ='1. Giả định & Thông số'!B22*'1. Giả định & Thông số'!$J$22*12 -> 96 | C5: ='1. Giả định & Thông số'!$C$22*'1. Giả định & Thông số'!$J$22*12*(1+'1. Giả định & Thông số'!$B$27)^0 -> 192 | D5: ='1. Giả định & Thông số'!$D$22*'1. Giả định & Thông số'!$J$22*12*(1+'1. Giả định & Thông số'!$B$27)^1 -> 201.6 | E5: ='1. Giả định & Thông số'!$E$22*'1. Giả định & Thông số'!$J$22*12*(1+'1. Giả định & Thông số'!$B$27)^2 -> 317.52 | F5: ='1. Giả định & Thông số'!$F$22*'1. Giả định & Thông số'!$J$22*12*(1+'1. Giả định & Thông số'!$B$27)^3 -> 444.528 | G5: ='1. Giả định & Thông số'!$G$22*'1. Giả định & Thông số'!$J$22*12*(1+'1. Giả định & Thông số'!$B$27)^4 -> 466.7544 | H5: ='1. Giả định & Thông số'!$H$22*'1. Giả định & Thông số'!$J$22*12*(1+'1. Giả định & Thông số'!$B$27)^5 -> 490.09212 | I5: ='1. Giả định & Thông số'!$I$22*'1. Giả định & Thông số'!$J$22*12*(1+'1. Giả định & Thông số'!$B$27)^6 -> 514.59673
A6: Nhân sự vận hành | B6: ='1. Giả định & Thông số'!B23*'1. Giả định & Thông số'!$J$23*12 -> 84 | C6: ='1. Giả định & Thông số'!$C$23*'1. Giả định & Thông số'!$J$23*12*(1+'1. Giả định & Thông số'!$B$27)^0 -> 84 | D6: ='1. Giả định & Thông số'!$D$23*'1. Giả định & Thông số'!$J$23*12*(1+'1. Giả định & Thông số'!$B$27)^1 -> 88.2 | E6: ='1. Giả định & Thông số'!$E$23*'1. Giả định & Thông số'!$J$23*12*(1+'1. Giả định & Thông số'!$B$27)^2 -> 92.61 | F6: ='1. Giả định & Thông số'!$F$23*'1. Giả định & Thông số'!$J$23*12*(1+'1. Giả định & Thông số'!$B$27)^3 -> 194.481 | G6: ='1. Giả định & Thông số'!$G$23*'1. Giả định & Thông số'!$J$23*12*(1+'1. Giả định & Thông số'!$B$27)^4 -> 204.20505 | H6: ='1. Giả định & Thông số'!$H$23*'1. Giả định & Thông số'!$J$23*12*(1+'1. Giả định & Thông số'!$B$27)^5 -> 214.4153 | I6: ='1. Giả định & Thông số'!$I$23*'1. Giả định & Thông số'!$J$23*12*(1+'1. Giả định & Thông số'!$B$27)^6 -> 225.13607
A7: Nhân sự Marketing | B7: ='1. Giả định & Thông số'!B24*'1. Giả định & Thông số'!$J$24*12 -> 72 | C7: ='1. Giả định & Thông số'!$C$24*'1. Giả định & Thông số'!$J$24*12*(1+'1. Giả định & Thông số'!$B$27)^0 -> 72 | D7: ='1. Giả định & Thông số'!$D$24*'1. Giả định & Thông số'!$J$24*12*(1+'1. Giả định & Thông số'!$B$27)^1 -> 75.6 | E7: ='1. Giả định & Thông số'!$E$24*'1. Giả định & Thông số'!$J$24*12*(1+'1. Giả định & Thông số'!$B$27)^2 -> 158.76 | F7: ='1. Giả định & Thông số'!$F$24*'1. Giả định & Thông số'!$J$24*12*(1+'1. Giả định & Thông số'!$B$27)^3 -> 166.698 | G7: ='1. Giả định & Thông số'!$G$24*'1. Giả định & Thông số'!$J$24*12*(1+'1. Giả định & Thông số'!$B$27)^4 -> 262.54935 | H7: ='1. Giả định & Thông số'!$H$24*'1. Giả định & Thông số'!$J$24*12*(1+'1. Giả định & Thông số'!$B$27)^5 -> 275.67682 | I7: ='1. Giả định & Thông số'!$I$24*'1. Giả định & Thông số'!$J$24*12*(1+'1. Giả định & Thông số'!$B$27)^6 -> 289.46066
A8: Nhân sự Finance/Kế toán | B8: ='1. Giả định & Thông số'!B25*'1. Giả định & Thông số'!$J$25*12 -> 72 | C8: ='1. Giả định & Thông số'!$C$25*'1. Giả định & Thông số'!$J$25*12*(1+'1. Giả định & Thông số'!$B$27)^0 -> 72 | D8: ='1. Giả định & Thông số'!$D$25*'1. Giả định & Thông số'!$J$25*12*(1+'1. Giả định & Thông số'!$B$27)^1 -> 75.6 | E8: ='1. Giả định & Thông số'!$E$25*'1. Giả định & Thông số'!$J$25*12*(1+'1. Giả định & Thông số'!$B$27)^2 -> 79.38 | F8: ='1. Giả định & Thông số'!$F$25*'1. Giả định & Thông số'!$J$25*12*(1+'1. Giả định & Thông số'!$B$27)^3 -> 166.698 | G8: ='1. Giả định & Thông số'!$G$25*'1. Giả định & Thông số'!$J$25*12*(1+'1. Giả định & Thông số'!$B$27)^4 -> 175.0329 | H8: ='1. Giả định & Thông số'!$H$25*'1. Giả định & Thông số'!$J$25*12*(1+'1. Giả định & Thông số'!$B$27)^5 -> 275.67682 | I8: ='1. Giả định & Thông số'!$I$25*'1. Giả định & Thông số'!$J$25*12*(1+'1. Giả định & Thông số'!$B$27)^6 -> 289.46066
A9: Nhân sự CSKH | B9: ='1. Giả định & Thông số'!B26*'1. Giả định & Thông số'!$J$26*12 -> 0 | C9: ='1. Giả định & Thông số'!$C$26*'1. Giả định & Thông số'!$J$26*12*(1+'1. Giả định & Thông số'!$B$27)^0 -> 84 | D9: ='1. Giả định & Thông số'!$D$26*'1. Giả định & Thông số'!$J$26*12*(1+'1. Giả định & Thông số'!$B$27)^1 -> 176.4 | E9: ='1. Giả định & Thông số'!$E$26*'1. Giả định & Thông số'!$J$26*12*(1+'1. Giả định & Thông số'!$B$27)^2 -> 185.22 | F9: ='1. Giả định & Thông số'!$F$26*'1. Giả định & Thông số'!$J$26*12*(1+'1. Giả định & Thông số'!$B$27)^3 -> 194.481 | G9: ='1. Giả định & Thông số'!$G$26*'1. Giả định & Thông số'!$J$26*12*(1+'1. Giả định & Thông số'!$B$27)^4 -> 204.20505 | H9: ='1. Giả định & Thông số'!$H$26*'1. Giả định & Thông số'!$J$26*12*(1+'1. Giả định & Thông số'!$B$27)^5 -> 321.62295 | I9: ='1. Giả định & Thông số'!$I$26*'1. Giả định & Thông số'!$J$26*12*(1+'1. Giả định & Thông số'!$B$27)^6 -> 337.7041
A10: TỔNG NHÂN SỰ | B10: =SUM(B3:B9) -> 444 | C10: =SUM(C4:C9) -> 624 | D10: =SUM(D4:D9) -> 743.4 | E10: =SUM(E4:E9) -> 965.79 | F10: =SUM(F4:F9) -> 1444.716 | G10: =SUM(G4:G9) -> 1604.4682 | H10: =SUM(H4:H9) -> 1883.7916 | I10: =SUM(I4:I9) -> 1977.9812
A12: II. CHI PHÍ CÔNG NGHỆ & HẠ TẦNG
A13: Duy trì công nghệ | B13: - | C13: ='1. Giả định & Thông số'!$B$42*'1. Giả định & Thông số'!$B$5 -> 270 | D13: ='1. Giả định & Thông số'!$B$42*'1. Giả định & Thông số'!$B$5 -> 270 | E13: ='1. Giả định & Thông số'!$B$42*'1. Giả định & Thông số'!$B$5 -> 270 | F13: ='1. Giả định & Thông số'!$B$42*'1. Giả định & Thông số'!$B$5 -> 270 | G13: ='1. Giả định & Thông số'!$B$42*'1. Giả định & Thông số'!$B$5 -> 270 | H13: ='1. Giả định & Thông số'!$B$42*'1. Giả định & Thông số'!$B$5 -> 270 | I13: ='1. Giả định & Thông số'!$B$42*'1. Giả định & Thông số'!$B$5 -> 270
A14: Hoạt động nền tảng (server, API, IoT, data) | B14: - | C14: ='1. Giả định & Thông số'!$B$39*'2. Báo cáo Ngân lưu'!C15 -> 510 | D14: ='1. Giả định & Thông số'!$B$39*'2. Báo cáo Ngân lưu'!D15 -> 695.68 | E14: ='1. Giả định & Thông số'!$B$39*'2. Báo cáo Ngân lưu'!E15 -> 1077.12 | F14: ='1. Giả định & Thông số'!$B$39*'2. Báo cáo Ngân lưu'!F15 -> 1494.4 | G14: ='1. Giả định & Thông số'!$B$39*'2. Báo cáo Ngân lưu'!G15 -> 1932.48 | H14: ='1. Giả định & Thông số'!$B$39*'2. Báo cáo Ngân lưu'!H15 -> 2178 | I14: ='1. Giả định & Thông số'!$B$39*'2. Báo cáo Ngân lưu'!I15 -> 2421.21
A15: TỔNG CÔNG NGHỆ & HẠ TẦNG | B15: - | C15: =Sum(C13:C14) -> 780 | D15: =Sum(D13:D14) -> 965.68 | E15: =Sum(E13:E14) -> 1347.12 | F15: =Sum(F13:F14) -> 1764.4 | G15: =Sum(G13:G14) -> 2202.48 | H15: =Sum(H13:H14) -> 2448 | I15: =Sum(I13:I14) -> 2691.21
A17: III. CHI PHÍ MARKETING & R&D
A18: Marketing (15% DT) | B18: - | C18: ='1. Giả định & Thông số'!$B$40*'2. Báo cáo Ngân lưu'!C15 -> 306 | D18: ='1. Giả định & Thông số'!$B$40*'2. Báo cáo Ngân lưu'!D15 -> 417.408 | E18: ='1. Giả định & Thông số'!$B$40*'2. Báo cáo Ngân lưu'!E15 -> 646.272 | F18: ='1. Giả định & Thông số'!$B$40*'2. Báo cáo Ngân lưu'!F15 -> 896.64 | G18: ='1. Giả định & Thông số'!$B$40*'2. Báo cáo Ngân lưu'!G15 -> 1159.488 | H18: ='1. Giả định & Thông số'!$B$40*'2. Báo cáo Ngân lưu'!H15 -> 1306.8 | I18: ='1. Giả định & Thông số'!$B$40*'2. Báo cáo Ngân lưu'!I15 -> 1452.726
A19: R&D (12% DT) | B19: - | C19: ='1. Giả định & Thông số'!$B$41*'2. Báo cáo Ngân lưu'!C15 -> 255 | D19: ='1. Giả định & Thông số'!$B$41*'2. Báo cáo Ngân lưu'!D15 -> 347.84 | E19: ='1. Giả định & Thông số'!$B$41*'2. Báo cáo Ngân lưu'!E15 -> 538.56 | F19: ='1. Giả định & Thông số'!$B$41*'2. Báo cáo Ngân lưu'!F15 -> 747.2 | G19: ='1. Giả định & Thông số'!$B$41*'2. Báo cáo Ngân lưu'!G15 -> 966.24 | H19: ='1. Giả định & Thông số'!$B$41*'2. Báo cáo Ngân lưu'!H15 -> 1089 | I19: ='1. Giả định & Thông số'!$B$41*'2. Báo cáo Ngân lưu'!I15 -> 1210.605
A20: TỔNG MKT & R&D | B20: - | C20: =sum(C18,C19) -> 561 | D20: =sum(D18,D19) -> 765.248 | E20: =sum(E18,E19) -> 1184.832 | F20: =sum(F18,F19) -> 1643.84 | G20: =sum(G18,G19) -> 2125.728 | H20: =sum(H18,H19) -> 2395.8 | I20: =sum(I18,I19) -> 2663.331
A22: IV. CHI PHÍ CỐ ĐỊNH
A23: Quản lý & Hành chính (VP, điện, nước…) | B23: - | C23: ='1. Giả định & Thông số'!$B$43 -> 240 | D23: ='1. Giả định & Thông số'!$B$43 -> 240 | E23: ='1. Giả định & Thông số'!$B$43 -> 240 | F23: ='1. Giả định & Thông số'!$B$43 -> 240 | G23: ='1. Giả định & Thông số'!$B$43 -> 240 | H23: ='1. Giả định & Thông số'!$B$43 -> 240 | I23: ='1. Giả định & Thông số'!$B$43 -> 240
A24: Tài chính & Pháp lý định kỳ | B24: - | C24: ='1. Giả định & Thông số'!$B$44 -> 30 | D24: ='1. Giả định & Thông số'!$B$44 -> 30 | E24: ='1. Giả định & Thông số'!$B$44 -> 30 | F24: ='1. Giả định & Thông số'!$B$44 -> 30 | G24: ='1. Giả định & Thông số'!$B$44 -> 30 | H24: ='1. Giả định & Thông số'!$B$44 -> 30 | I24: ='1. Giả định & Thông số'!$B$44 -> 30
A25: TỔNG CHI PHÍ CỐ ĐỊNH | B25: - | C25: =sum(C23,C24) -> 270 | D25: =sum(D23,D24) -> 270 | E25: =sum(E23,E24) -> 270 | F25: =sum(F23,F24) -> 270 | G25: =sum(G23,G24) -> 270 | H25: =sum(H23,H24) -> 270 | I25: =sum(I23,I24) -> 270
A27: TỔNG CHI PHÍ VẬN HÀNH | B27: - | C27: =C10+C15+C20+C25 -> 2235 | D27: =D10+D15+D20+D25 -> 2744.328 | E27: =E10+E15+E20+E25 -> 3767.742 | F27: =F10+F15+F20+F25 -> 5122.956 | G27: =G10+G15+G20+G25 -> 6202.6763 | H27: =H10+H15+H20+H25 -> 6997.5916 | I27: =I10+I15+I20+I25 -> 7602.5222

Sheet 4. Báo cáo Thu nhập
A1: BÁO CÁO THU NHẬP - CHAMP MẠNH CHAT (Đơn vị: Triệu VND)
A2: KHOẢN MỤC | B2: Năm 0 (Đầu tư) | C2: Năm 1 | D2: Năm 2 | E2: Năm 3 | F2: Năm 4 | G2: Năm 5 | H2: Năm 6 | I2: Năm 7
A3: TỔNG DOANH THU | B3: - | C3: ='2. Báo cáo Ngân lưu'!C15 -> 2550 | D3: ='2. Báo cáo Ngân lưu'!D15 -> 3478.4 | E3: ='2. Báo cáo Ngân lưu'!E15 -> 5385.6 | F3: ='2. Báo cáo Ngân lưu'!F15 -> 7472 | G3: ='2. Báo cáo Ngân lưu'!G15 -> 9662.4 | H3: ='2. Báo cáo Ngân lưu'!H15 -> 10890 | I3: ='2. Báo cáo Ngân lưu'!I15 -> 12106.05
A4: Phí sử dụng app | B4: - | C4: ='2. Báo cáo Ngân lưu'!C5 -> 2340 | D4: ='2. Báo cáo Ngân lưu'!D5 -> 3120 | E4: ='2. Báo cáo Ngân lưu'!E5 -> 4680 | F4: ='2. Báo cáo Ngân lưu'!F5 -> 6240 | G4: ='2. Báo cáo Ngân lưu'!G5 -> 7020 | H4: ='2. Báo cáo Ngân lưu'!H5 -> 7800 | I4: ='2. Báo cáo Ngân lưu'!I5 -> 8580
A5: Hoa hồng bảo hiểm | B5: - | C5: ='2. Báo cáo Ngân lưu'!C8 | D5: ='2. Báo cáo Ngân lưu'!D8 | E5: ='2. Báo cáo Ngân lưu'!E8 | F5: ='2. Báo cáo Ngân lưu'!F8 | G5: ='2. Báo cáo Ngân lưu'!G8 | H5: ='2. Báo cáo Ngân lưu'!H8 | I5: ='2. Báo cáo Ngân lưu'!I8
A6: Hoa hồng DN & NH | B6: - | C6: ='2. Báo cáo Ngân lưu'!C11 -> 210 | D6: ='2. Báo cáo Ngân lưu'!D11 -> 358.4 | E6: ='2. Báo cáo Ngân lưu'!E11 -> 705.6 | F6: ='2. Báo cáo Ngân lưu'!F11 -> 1232 | G6: ='2. Báo cáo Ngân lưu'!G11 -> 1764 | H6: ='2. Báo cáo Ngân lưu'!H11 -> 2100 | I6: ='2. Báo cáo Ngân lưu'!I11 -> 2425.5
A7: (-) Chi phí vận hành | B7: - | C7: ='3. Chi phí chi tiết'!C27 -> 2235 | D7: ='3. Chi phí chi tiết'!D27 -> 2744.328 | E7: ='3. Chi phí chi tiết'!E27 -> 3767.742 | F7: ='3. Chi phí chi tiết'!F27 -> 5122.956 | G7: ='3. Chi phí chi tiết'!G27 -> 6202.6763 | H7: ='3. Chi phí chi tiết'!H27 -> 6997.5916 | I7: ='3. Chi phí chi tiết'!I27 -> 7602.5222
A8: (-) Khấu hao tài sản | B8: - | C8: ='7. Lạm phát & Khấu hao'!D43 -> 630.57143 | D8: ='7. Lạm phát & Khấu hao'!E43 -> 620.57143 | E8: ='7. Lạm phát & Khấu hao'!F43 -> 620.57143 | F8: ='7. Lạm phát & Khấu hao'!G43 -> 320.57143 | G8: ='7. Lạm phát & Khấu hao'!H43 -> 320.57143 | H8: ='7. Lạm phát & Khấu hao'!I43 -> 257.14286 | I8: ='7. Lạm phát & Khấu hao'!J43 -> 257.14286
A9: EBIT | B9: - | C9: =C3-C7-C8 -> -315.57143 | D9: =D3-D7-D8 -> 113.50057 | E9: =E3-E7-E8 -> 997.28657 | F9: =F3-F7-F8 -> 2028.4726 | G9: =G3-G7-G8 -> 3139.1523 | H9: =H3-H7-H8 -> 3635.2656 | I9: =I3-I7-I8 -> 4246.385
A10: (-) Lãi vay | B10: - | C10: ='5. Lịch trả nợ'!C5 -> 138.776 | D10: ='5. Lịch trả nợ'!D5 -> 109.3102 | E10: ='5. Lịch trả nợ'!E5 -> 76.603158 | F10: ='5. Lịch trả nợ'!F5 -> 40.298344 | G10: ='5. Lịch trả nợ'!G5 -> 0 | H10: ='5. Lịch trả nợ'!H5 -> 0 | I10: ='5. Lịch trả nợ'!I5 -> 0
A11: LỢI NHUẬN TRƯỚC THUẾ (EBT) | B11: - | C11: =C9-C10 -> -454.34743 | D11: =D9-D10 -> 4.1903724 | E11: =E9-E10 -> 920.68341 | F11: =F9-F10 -> 1988.1742 | G11: =G9-G10 -> 3139.1523 | H11: =H9-H10 -> 3635.2656 | I11: =I9-I10 -> 4246.385
A12: (-) Thuế TNDN (20%) | B12: - | C12: =IF(C11>0,C11*0.2,0) -> 0 | D12: =IF(D11>0,D11*0.2,0) -> 0.83807448 | E12: =IF(E11>0,E11*0.2,0) -> 184.13668 | F12: =IF(F11>0,F11*0.2,0) -> 397.63485 | G12: =IF(G11>0,G11*0.2,0) -> 627.83046 | H12: =IF(H11>0,H11*0.2,0) -> 727.05311 | I12: =IF(I11>0,I11*0.2,0) -> 849.277
A13: THU NHẬP RÒNG (NI) | B13: - | C13: =C11-C12 -> -454.34743 | D13: =D11-D12 -> 3.3522979 | E13: =E11-E12 -> 736.54673 | F13: =F11-F12 -> 1590.5394 | G13: =G11-G12 -> 2511.3219 | H13: =H11-H12 -> 2908.2124 | I13: =I11-I12 -> 3397.108
A14: Biên lợi nhuận ròng (%) | B14: - | C14: =IF(C3>0,C13/C3,"N/A") -> -0.17817546 | D14: =IF(D3>0,D13/D3,"N/A") -> 0.0009637471 | E14: =IF(E3>0,E13/E3,"N/A") -> 0.13676224 | F14: =IF(F3>0,F13/F3,"N/A") -> 0.21286662 | G14: =IF(G3>0,G13/G3,"N/A") -> 0.25990663 | H14: =IF(H3>0,H13/H3,"N/A") -> 0.26705348 | I14: =IF(I3>0,I13/I3,"N/A") -> 0.28061242

Sheet 5. Lịch trả nợ
A1: LỊCH TRẢ NỢ - CHAMP MẠNH CHAT (Đơn vị: Triệu VND)
A2: KHOẢN MỤC | B2: Năm 0 (Đầu tư) | C2: Năm 1 | D2: Năm 2 | E2: Năm 3 | F2: Năm 4 | G2: Năm 5 | H2: Năm 6 | I2: Năm 7
A4: Dư nợ đầu kỳ | B4: - | C4: ='1. Giả định & Thông số'!$B$12 -> 1261.6 | D4: =MAX(0, C8) -> 993.72907 | E4: =MAX(0, D8) -> 696.39235 | F4: =MAX(0, E8) -> 366.34858 | G4: =MAX(0,F8) -> 0 | H4: =MAX(0, G8) -> 0 | I4: =MAX(0, H8) -> 0
A5: Lãi phát sinh (10%) | B5: - | C5: =IF(C4>0, C4*'1. Giả định & Thông số'!$B$14, 0) -> 138.776 | D5: =IF(D4>0, D4*'1. Giả định & Thông số'!$B$14, 0) -> 109.3102 | E5: =IF(E4>0, E4*'1. Giả định & Thông số'!$B$14, 0) -> 76.603158 | F5: =IF(F4>0, F4*'1. Giả định & Thông số'!$B$14, 0) -> 40.298344 | G5: =IF(G4>0, G4*'1. Giả định & Thông số'!$B$14, 0) -> 0 | H5: =IF(H4>0, H4*'1. Giả định & Thông số'!$B$14, 0) -> 0 | I5: =IF(I4>0, I4*'1. Giả định & Thông số'!$B$14, 0) -> 0
A6: Trả nợ gốc | B6: - | C6: =IF(C4>0, MIN(C4, C7-C5), 0) -> 267.87093 | D6: =IF(D4>0, MIN(D4, D7-D5), 0) -> 297.33673 | E6: =IF(E4>0, MIN(E4, E7-E5), 0) -> 330.04377 | F6: =IF(F4>0, MIN(F4, F7-F5), 0) -> 366.34858 | G6: =IF(G4>0, MIN(G4, G7-G5), 0) -> 0 | H6: =IF(H4>0, MIN(H4, H7-H5), 0) -> 0 | I6: =IF(I4>0, MIN(I4, I7-I5), 0) -> 0
A7: TỔNG THANH TOÁN | B7: - | C7: =IF(C4>0, '1. Giả định & Thông số'!$B$12*'1. Giả định & Thông số'!$B$14/(1-(1+'1. Giả định & Thông số'!$B$14)^(-'1. Giả định & Thông số'!$B$18)), 0) -> 406.64693 | D7: =IF(D4>0, '1. Giả định & Thông số'!$B$12*'1. Giả định & Thông số'!$B$14/(1-(1+'1. Giả định & Thông số'!$B$14)^(-'1. Giả định & Thông số'!$B$18)), 0) -> 406.64693 | E7: =IF(E4>0, '1. Giả định & Thông số'!$B$12*'1. Giả định & Thông số'!$B$14/(1-(1+'1. Giả định & Thông số'!$B$14)^(-'1. Giả định & Thông số'!$B$18)), 0) -> 406.64693 | F7: =IF(F4>0, '1. Giả định & Thông số'!$B$12*'1. Giả định & Thông số'!$B$14/(1-(1+'1. Giả định & Thông số'!$B$14)^(-'1. Giả định & Thông số'!$B$18)), 0) -> 406.64693 | G7: =IF(ROUND(G4, 2)>0, '1. Giả định & Thông số'!$B$12*'1. Giả định & Thông số'!$B$14/(1-(1+'1. Giả định & Thông số'!$B$14)^(-'1. Giả định & Thông số'!$B$18)), 0) -> 0 | H7: =IF(ROUND(H4, 2)>0, '1. Giả định & Thông số'!$B$12*'1. Giả định & Thông số'!$B$14/(1-(1+'1. Giả định & Thông số'!$B$14)^(-'1. Giả định & Thông số'!$B$18)), 0) -> 0 | I7: =IF(ROUND(I4, 2)>0, '1. Giả định & Thông số'!$B$12*'1. Giả định & Thông số'!$B$14/(1-(1+'1. Giả định & Thông số'!$B$14)^(-'1. Giả định & Thông số'!$B$18)), 0) -> 0
A8: Dư nợ cuối kỳ | B8: ='1. Giả định & Thông số'!$B$12 -> 1261.6 | C8: =C4-C6 -> 993.72907 | D8: =D4-D6 -> 696.39235 | E8: =E4-E6 -> 366.34858 | F8: =F4-F6 -> 0 | G8: =G4-G6 -> 0 | H8: =H4-H6 -> 0 | I8: =I4-I6 -> 0

Sheet 6. Đánh Giá Tài Chính
A1: CHAMP MẠNH CHAT - ĐÁNH GIÁ HIỆU QUẢ TÀI CHÍNH DỰ ÁN
A2: Đơn vị: Triệu VND | Quan điểm: Chủ sở hữu (EPV) | Năm tính: 2026-2031 (5 năm)
A3: CHỈ TIÊU | B3: GIÁ TRỊ | C3: KẾT QUẢ / ĐÁNH GIÁ | D3: NHẬN XÉT CHI TIẾT
A4: A. CÁC CHỈ TIÊU TÀI CHÍNH CHÍNH (QUAN ĐIỂM VỐN CHỦ SỞ HỮU - EPV)
A5: NPV - Giá trị hiện tại thuần (Net Present Value) | B5: ='2. Báo cáo Ngân lưu'!B63 -> 3410.8298 | C5: =IF(B5>0," NPV > 0 → Dự án khả thi tạo giá trị","NPV < 0 → Cần xem xét lại") -> NPV > 0 → Dự án khả thi tạo giá trị | D5: NPV > 0: Dự án tạo ra giá trị vượt trên chi phí vốn (WACC).
A6: IRR - Tỷ suất sinh lời nội bộ (Internal Rate of Return) | B6: ='2. Báo cáo Ngân lưu'!B64 -> 0.37986738 | C6: =IF(ISNUMBER(B6),IF(B6>'1. Giả định & Thông số'!$B$17," IRR > WACC → Dự án sinh lợi vượt chi phí vốn","⚠ IRR < WACC → Cần xem xét lại"),"N/A") -> IRR > WACC → Dự án sinh lợi vượt chi phí vốn | D6: IRR là lãi suất làm NPV = 0. Nếu IRR > WACC (14.32%), dự án sinh lợi vượt chi phí vốn. IRR 36.64% >> WACC 14.32% → Dự án tạo ra giá trị vượt trội. Vòng đời 7 năm (2026-2034). | F6: BD: CÔNG THỨC ĐỀ XUẤT
A7: MIRR - IRR điều chỉnh (Modified IRR, tái đầu tư = WACC) | B7: =IFERROR(MIRR('2. Báo cáo Ngân lưu'!B55:I55,'1. Giả định & Thông số'!$B$17,'1. Giả định & Thông số'!$B$17),"N/A") -> 0.30702431 | C7: =IF(ISNUMBER(B7),IF(B7>'1. Giả định & Thông số'!$B$17," MIRR > WACC → Khả thi","⚠ MIRR < WACC → Xem lại"),"N/A") -> MIRR > WACC → Khả thi | D7: MIRR thực tế hơn IRR vì giả định tái đầu tư dòng tiền dương ở mức WACC (không phải IRR). Phù hợp đánh giá dự án startup giai đoạn đầu thua lỗ.
A8: BCR - Tỷ số lợi ích / chi phí (Benefit-Cost Ratio) | B8: =('2. Báo cáo Ngân lưu'!B63 + ABS('2. Báo cáo Ngân lưu'!B55)) / ABS('2. Báo cáo Ngân lưu'!B55) -> 2.8023831 | C8: =IF(B8>=1," BCR ≥ 1 → Lợi ích vượt chi phí"," BCR < 1 → Chi phí > lợi ích") -> BCR ≥ 1 → Lợi ích vượt chi phí | D8: BCR = (NPV + Equity ban đầu) / Equity ban đầu. BCR > 1 = mỗi đồng vốn thu về nhiều hơn 1 đồng (đã chiết khấu).
A9: EAB - Lợi ích đều quy năm (Equivalent Annual Benefit) | B9: =B5*'1. Giả định & Thông số'!$B$17/(1-(1+'1. Giả định & Thông số'!$B$17)^(-7)) -> 803.1714 | C9: =IF(B9>0," EAB > 0 → Dự án có lợi nhuận hàng năm"," EAB ≤ 0") -> EAB > 0 → Dự án có lợi nhuận hàng năm | D9: EAB phân bổ đều NPV thành lợi ích năm bình quân trong suốt vòng đời dự án. Giúp so sánh các dự án có thời gian khác nhau.
A10: PP - Thời gian hoàn vốn (Payback Period, không chiết khấu) | B10: ='2. Báo cáo Ngân lưu'!B66 -> 3.87
A11: DPP - Thời gian hoàn vốn chiết khấu (Discounted Payback Period)
A12: WACC - Chi phí vốn bình quân gia quyền | B12: ='1. Giả định & Thông số'!$B$17 -> 0.1432 | C12: ='1. Giả định & Thông số'!C20&" = Re×E/V + Rd×(1-T)×D/V" -> N1 = Re×E/V + Rd×(1-T)×D/V
A14: B. PHÂN TÍCH ĐỘ NHẠY (SENSITIVITY ANALYSIS) - NPV THEO KỊCH BẢN DOANH THU
A15: KỊCH BẢN | B15: HỆ SỐ ĐIỀU CHỈNH DOANH THU | C15: NPV ƯỚC TÍNH (Tr.VND) | D15: NHẬN XÉT
A16: Bi quan - Tăng trưởng chậm (50% DT) | B16: {=NPV('1. Giả định & Thông số'!B17,'2. Báo cáo Ngân lưu'!C55:G55)*0.5+'2. Báo cáo Ngân lưu'!B55} -> -614.48159 | C16: =IF(B16>0,"Khả thi"," Không khả thi") -> Không khả thi | D16: Thị trường fintech nông nghiệp cạnh tranh cao
A17: Thận trọng - Dưới kỳ vọng (75% DT) | B17: {=NPV('1. Giả định & Thông số'!B17,'2. Báo cáo Ngân lưu'!C55:G55)*0.75+'2. Báo cáo Ngân lưu'!B55} -> 24.47761 | C17: =IF(B17>0," Khả thi"," Không khả thi") -> Khả thi | D17: DN onboarding chậm hơn kế hoạch, một số hợp đồng bị trì hoãn
A18: Cơ sở - Đúng kế hoạch (100% DT) | B18: ='2. Báo cáo Ngân lưu'!B63 -> 3410.8298 | C18: =IF(B18>0," Khả thi"," Không khả thi") -> Khả thi | D18: Kịch bản chuẩn; hoa hồng BH & NH theo giả định
A19: Lạc quan - Vượt kế hoạch (125% DT) | B19: {=NPV('1. Giả định & Thông số'!B17,'2. Báo cáo Ngân lưu'!C55:G55)*1.25+'2. Báo cáo Ngân lưu'!B55} -> 1302.396 | C19: =IF(B19>0,"Khả thi","Không khả thi") -> Khả thi | D19: Quan hệ đối tác tốt, mở rộng nhanh
A20: Tốt nhất - Bứt phá (150% DT) | B20: {=NPV('1. Giả định & Thông số'!B17,'2. Báo cáo Ngân lưu'!C55:G55)*1.5+'2. Báo cáo Ngân lưu'!B55} -> 1941.3552 | C20: =IF(B20>0,"Khả thi","Không khả thi") -> Khả thi | D20: Mô hình nhân rộng mạnh, partnership ngân hàng lớn từ năm 2
A22: C. PHÂN TÍCH ĐỘ NHẠY - NPV THEO WACC (CHI PHÍ VỐN)
A23: MỨC WACC | B23: MÔ TẢ | C23: NPV ƯỚC TÍNH (Tr.VND) | D23: Ý NGHĨA
A24: 0.1 | B24: Thấp - Lãi suất giảm / rủi ro thấp hơn | C24: {=NPV(0.1,'2. Báo cáo Ngân lưu'!C55:I55)+'2. Báo cáo Ngân lưu'!B55} -> 4679.2486 | D24: =IF(C24>0,"Khả thi","Không khả thi → review kịch bản") -> Khả thi
A25: 0.1264 | B25: Thận trọng (WACC giảm, Re=18%) | C25: {=NPV(0.1264,'2. Báo cáo Ngân lưu'!C55:I55)+'2. Báo cáo Ngân lưu'!B55} -> 3865.4188 | D25: =IF(C25>0,"Khả thi","Không khả thi → review kịch bản") -> Khả thi
A26: 0.1432 | B26: Cơ sở (WACC hiện tại = 14,32%) | C26: {=NPV(0.1432,'2. Báo cáo Ngân lưu'!C55:I55)+'2. Báo cáo Ngân lưu'!B55} -> 3410.8298 | D26: =IF(C26>0,"Khả thi","Không khả thi → review kịch bản") -> Khả thi
A27: 0.2 | B27: Cao - Rủi ro tăng / lạm phát | C27: {=NPV(0.2,'2. Báo cáo Ngân lưu'!C55:I55)+'2. Báo cáo Ngân lưu'!B55} -> 2164.3051 | D27: =IF(C27>0,"Khả thi","Không khả thi → review kịch bản") -> Khả thi
A28: 0.25 | B28: Rất cao - Giai đoạn khủng hoảng | C28: {=NPV(0.25,'2. Báo cáo Ngân lưu'!C55:I55)+'2. Báo cáo Ngân lưu'!B55} -> 1349.9971 | D28: =IF(C28>0,"Khả thi","Không khả thi → review kịch bản") -> Khả thi

Sheet 7. Lạm phát & Khấu hao
A1: PHÂN TÍCH LẠM PHÁT & KHẤU HAO - CHAMP MẠNH CHAT (Đơn vị: Triệu VND)
A4: I. GIẢ ĐỊNH LẠM PHÁT (INFLATION ASSUMPTIONS)
A5: Chỉ tiêu | B5: Đơn vị | C5: Năm 0 | D5: Năm 1 | E5: Năm 2 | F5: Năm 3 | G5: Năm 4 | H5: Năm 5 | I5: Năm 6 | J5: Năm 7
A6: Tỷ lệ lạm phát giả định (CPI VN) | B6: %/năm | C6: - | D6: 0.045 | E6: 0.045 | F6: 0.045 | G6: 0.045 | H6: 0.045 | I6: 0.045 | J6: 0.045
A7: Tỷ lệ lạm phát nhân sự (lương) | B7: %/năm | C7: - | D7: 0.07 | E7: 0.07 | F7: 0.07 | G7: 0.07 | H7: 0.07 | I7: 0.07 | J7: 0.07
A8: Tỷ lệ lạm phát chi phí vận hành | B8: %/năm | C8: - | D8: 0.04 | E8: 0.04 | F8: 0.04 | G8: 0.04 | H8: 0.04 | I8: 0.04 | J8: 0.04
A9: Tỷ lệ lạm phát chi phí công nghệ | B9: %/năm | C9: - | D9: 0.03 | E9: 0.03 | F9: 0.03 | G9: 0.03 | H9: 0.03 | I9: 0.03 | J9: 0.03
A10: → Chỉ số giá tích lũy (CPI Index, Năm 0 = 1.000)
A11: Chỉ tiêu | B11: Đơn vị | C11: Năm 0 | D11: Năm 1 | E11: Năm 2 | F11: Năm 3 | G11: Năm 4 | H11: Năm 5 | I11: Năm 6 | J11: Năm 7
A12: Chỉ số giá CPI (cơ sở) | B12: Lần | C12: 1 | D12: =C12*(1+$D$6) -> 1.045 | E12: =D12*(1+$D$6) -> 1.092025 | F12: =E12*(1+$D$6) -> 1.1411661 | G12: =F12*(1+$D$6) -> 1.1925186 | H12: =G12*(1+$D$6) -> 1.2461819 | I12: =H12*(1+$D$6) -> 1.3022601 | J12: =I12*(1+$D$6) -> 1.3608618
A13: Chỉ số lương nhân sự | B13: Lần | C13: 1 | D13: =C13*(1+$D$7) -> 1.07 | E13: =D13*(1+$D$7) -> 1.1449 | F13: =E13*(1+$D$7) -> 1.225043 | G13: =F13*(1+$D$7) -> 1.310796 | H13: =G13*(1+$D$7) -> 1.4025517 | I13: =H13*(1+$D$7) -> 1.5007304 | J13: =I13*(1+$D$7) -> 1.6057815
A14: Chỉ số chi phí vận hành | B14: Lần | C14: 1 | D14: =C14*(1+$D$8) -> 1.04 | E14: =D14*(1+$D$8) -> 1.0816 | F14: =E14*(1+$D$8) -> 1.124864 | G14: =F14*(1+$D$8) -> 1.1698586 | H14: =G14*(1+$D$8) -> 1.2166529 | I14: =H14*(1+$D$8) -> 1.265319 | J14: =I14*(1+$D$8) -> 1.3159318
A15: Chỉ số chi phí công nghệ | B15: Lần | C15: 1 | D15: =C15*(1+$D$9) -> 1.03 | E15: =D15*(1+$D$9) -> 1.0609 | F15: =E15*(1+$D$9) -> 1.092727 | G15: =F15*(1+$D$9) -> 1.1255088 | H15: =G15*(1+$D$9) -> 1.1592741 | I15: =H15*(1+$D$9) -> 1.1940523 | J15: =I15*(1+$D$9) -> 1.2298739
A17: II. DOANH THU & CHI PHÍ ĐIỀU CHỈNH THEO LẠM PHÁT (Triệu VND - Giá thực tế)
A18: Chỉ tiêu | B18: Đơn vị | C18: Năm 0 | D18: Năm 1 | E18: Năm 2 | F18: Năm 3 | G18: Năm 4 | H18: Năm 5 | I18: Năm 6 | J18: Năm 7
A19: Doanh thu danh nghĩa (Nominal - giá gốc) | B19: Tr.VND | C19: - | D19: ='2. Báo cáo Ngân lưu'!C15 -> 2550 | E19: ='2. Báo cáo Ngân lưu'!D15 -> 3478.4 | F19: ='2. Báo cáo Ngân lưu'!E15 -> 5385.6 | G19: ='2. Báo cáo Ngân lưu'!F15 -> 7472 | H19: ='2. Báo cáo Ngân lưu'!G15 -> 9662.4 | I19: ='2. Báo cáo Ngân lưu'!H15 -> 10890 | J19: ='2. Báo cáo Ngân lưu'!I15 -> 12106.05
A20: Doanh thu thực tế (Real - điều chỉnh CPI) | B20: Tr.VND | D20: =D19/D12 -> 2440.1914 | E20: =E19/E12 -> 3185.2751 | F20: =F19/F12 -> 4719.383 | G20: =G19/G12 -> 6265.7304 | H20: =H19/H12 -> 7753.603 | I20: =I19/I12 -> 8362.3846 | J20: =J19/J12 -> 8895.87
A21: Tăng trưởng DT thực tế (%) | B21: % | E21: =E20/D20-1 -> 0.30533821 | F21: =F20/E20-1 -> 0.48162495 | G21: =G20/F20-1 -> 0.3276588 | H21: =H20/G20-1 -> 0.23746196 | I21: =I20/H20-1 -> 0.078515962 | J21: =J20/I20-1 -> 0.063795853
A22: Chi phí vận hành danh nghĩa (Nominal) | B22: Tr.VND | C22: - | D22: ='3. Chi phí chi tiết'!C27 -> 2235 | E22: ='3. Chi phí chi tiết'!D27 -> 2744.328 | F22: ='3. Chi phí chi tiết'!E27 -> 3767.742 | G22: ='3. Chi phí chi tiết'!F27 -> 5122.956 | H22: ='3. Chi phí chi tiết'!G27 -> 6202.6763 | I22: ='3. Chi phí chi tiết'!H27 -> 6997.5916 | J22: ='3. Chi phí chi tiết'!I27 -> 7602.5222
A23: Chi phí vận hành thực tế (Real - điều chỉnh CPI) | B23: Tr.VND | D23: =D22/D13 -> 2088.785 | E23: =E22/E13 -> 2397.0024 | F23: =F22/F13 -> 3075.5998 | G23: =G22/G13 -> 3908.2786 | H23: =H22/H13 -> 4422.4224 | I23: =I22/I13 -> 4662.7907 | J23: =J22/J13 -> 4734.4687
A24: Lợi nhuận ròng thực tế (Real NI) | B24: Tr.VND | D24: =D20-D23 -> 351.40634 | E24: =E20-E23 -> 788.2727 | F24: =F20-F23 -> 1643.7832 | G24: =G20-G23 -> 2357.4518 | H24: =H20-H23 -> 3331.1806 | I24: =I20-I23 -> 3699.5939 | J24: =J20-J23 -> 4161.4013
A27: III. LỊCH KHẤU HAO TÀI SẢN CỐ ĐỊNH (DEPRECIATION SCHEDULE)
A28: Chỉ tiêu | B28: Đơn vị | C28: Năm 0 | D28: Năm 1 | E28: Năm 2 | F28: Năm 3 | G28: Năm 4 | H28: Năm 5 | I28: Năm 6 | J28: Năm 7
A29: → A. Thông số tài sản (Giả định khấu hao đường thẳng)
A30: Tài sản | B30: Nguyên giá (Tr.VND) | C30: Thời hạn KH (năm) | D30: Giá trị còn lại (Tr.VND) | E30: KH/Năm (Tr.VND)
A31: Chi phí phát triển ứng dụng (vốn hóa) | B31: ='1. Giả định & Thông số'!$B$5 -> 1800 | C31: 7 | D31: 0 | E31: =B31/C31 -> 257.14286
A32: Chi phí vật tư & thiết bị (PC, Laptop…) | B32: ='1. Giả định & Thông số'!$B$6 -> 444 | C32: 7 | D32: 0 | E32: =B32/C32 -> 63.428571
A33: Chi phí ra mắt & triển khai sản phẩm | B33: ='1. Giả định & Thông số'!$B$7 -> 900 | C33: 3 | D33: 0 | E33: =B33/C33 -> 300
A34: Chi phí thành lập doanh nghiệp | B34: ='1. Giả định & Thông số'!$B$4 -> 10 | C34: 1 | D34: 0 | E34: =B34/C34 -> 10
A35: TỔNG NGUYÊN GIÁ TÀI SẢN | B35: =SUM(B31:B34) -> 3154 | C35: - | D35: =SUM(D31:D34) -> 0 | E35: =SUM(E31:E34) -> 630.57143
A37: → B. Lịch khấu hao theo năm (Đường thẳng - Straight Line)
A38: Chỉ tiêu | B38: Đơn vị | C38: Năm 0 | D38: Năm 1 | E38: Năm 2 | F38: Năm 3 | G38: Năm 4 | H38: Năm 5 | I38: Năm 6 | J38: Năm 7
A39: KH - Phát triển ứng dụng | B39: - | C39: - | D39: =E31 -> 257.14286 | E39: =E31 -> 257.14286 | F39: =E31 -> 257.14286 | G39: =E31 -> 257.14286 | H39: =E31 -> 257.14286 | I39: =E31 -> 257.14286 | J39: =E31 -> 257.14286
A40: KH - Vật tư & thiết bị | B40: - | C40: - | D40: =E32 -> 63.428571 | E40: =E32 -> 63.428571 | F40: =E32 -> 63.428571 | G40: =E32 -> 63.428571 | H40: =E32 -> 63.428571 | I40: =F32 | J40: =G32
A41: KH - Ra mắt & triển khai SP | B41: - | C41: - | D41: =E33 -> 300 | E41: =E33 -> 300 | F41: =E33 -> 300 | G41: - | H41: - | I41: - | J41: -
A42: KH - Chi phí thành lập DN | B42: - | C42: - | D42: =E34 -> 10 | E42: - | F42: - | G42: - | H42: - | I42: - | J42: -
A43: TỔNG KHẤU HAO HÀNG NĂM | B43: Tr.VND | C43: - | D43: =SUM(D39:D42) -> 630.57143 | E43: =SUM(E39:E42) -> 620.57143 | F43: =SUM(F39:F42) -> 620.57143 | G43: =SUM(G39:G42) -> 320.57143 | H43: =SUM(H39:H42) -> 320.57143 | I43: =SUM(I39:I42) -> 257.14286 | J43: =SUM(J39:J42) -> 257.14286
A44: Khấu hao lũy kế | B44: Tr.VND | C44: - | D44: =D43 -> 630.57143 | E44: =D44+E43 -> 1251.1429 | F44: =E44+F43 -> 1871.7143 | G44: =F44+G43 -> 2192.2857 | H44: =G44+H43 -> 2512.8571 | I44: =H44+I43 -> 2770 | J44: =I44+J43 -> 3027.1429
A45: Giá trị còn lại (Net Book Value) | B45: Tr.VND | C45: =$B$35 -> 3154 | D45: =$B$35-D44 -> 2523.4286 | E45: =$B$35-E44 -> 1902.8571 | F45: =$B$35-F44 -> 1282.2857 | G45: =$B$35-G44 -> 961.71429 | H45: =$B$35-H44 -> 641.14286 | I45: =$B$35-I44 -> 384 | J45: =$B$35-J44 -> 126.85714
A46: Tỷ lệ KH/Nguyên giá (%) | B46: % | C46: - | D46: =D44/$B$35 -> 0.19992753 | E46: =E44/$B$35 -> 0.39668448 | F46: =F44/$B$35 -> 0.59344143 | G46: =G44/$B$35 -> 0.69508108 | H46: =H44/$B$35 -> 0.79672072 | I46: =I44/$B$35 -> 0.87824984 | J46: =J44/$B$35 -> 0.95977897
...
