Workbook

Sheet 1. Giả định & Thông số
A1: GIẢ ĐỊNH & THÔNG SỐ DỰ ÁN - CHAMP MẠNH CHAT
A2: Chỉ tiêu | B2: Giá trị | C2: Đơn vị | D2: Ghi chú
A3: A. ĐẦU TƯ BAN ĐẦU
A4: Chi phí thành lập doanh nghiệp | B4: 10 | C4: Triệu VND | D4: Thực tế: đăng ký, con dấu, pháp lý 2024-2025
A5: Chi phí phát triển ứng dụng | B5: 1800 | C5: Triệu VND | D5: MVP mobile app + AI cơ bản + API BH/NH - outsource VN ~$70-85k; phát triển theo giai đoạn
A6: Chi phí vật tư, thiết bị (PC, Laptop, Mạng, VP) | B6: 180 | C6: Triệu VND | D6: 5 laptop, 2 PC, router, UPS - giá thực tế VN 2024
A7: Chi phí ra mắt sản phẩm / triển khai | B7: 600 | C7: Triệu VND | D7: Pilot B2B tập trung: webinar online + onboarding digital (giảm chi phí thuê hội trường)
A8: → TỔNG ĐẦU TƯ BAN ĐẦU | B8: =B4+B5+B6+B7 -> 2590 | C8: Triệu VND | D8: Cập nhật theo giả định thực tế
A9: B. CẤU TRÚC VỐN
A10: Tỷ trọng vốn vay (D/V) | B10: 0.4 | C10: Tỷ lệ | D10: 40% - tăng tỷ trọng vay để tối ưu WACC (lãi vay có lợi thuế)
A11: Tỷ trọng vốn chủ sở hữu (E/V) | B11: 0.6 | C11: Tỷ lệ | D11: 60%
A12: Vốn vay (Debt) | B12: =B8*B10 -> 1036 | C12: Triệu VND | D12: Tổng đầu tư × 40%
A13: Vốn chủ sở hữu (Equity) | B13: =B8*B11 -> 1554 | C13: Triệu VND | D13: Tổng đầu tư × 60%
A14: Lãi suất vay (Rd) | B14: 0.11 | C14: Năm | D14: Lãi vay DN SME tại VN 2024-2025 (~10.5-12%)
A15: Chi phí vốn chủ (Re) | B15: 0.18 | C15: Năm | D15: Angel investor VN kỳ vọng 18-22%; dùng 18% để phản ánh dự án có dòng tiền rõ ràng
A16: Thuế TNDN (T) | B16: 0.2 | C16: Tỷ lệ | D16: Luật thuế TNDN VN
A17: WACC | B17: =B15*B11+B14*(1-B16)*B10 -> 0.1432 | C17: Năm | D17: Re×E/V + Rd×(1-T)×D/V | Cập nhật theo cấu trúc vốn mới
A18: Số kỳ vay / hoàn vốn | B18: 5 | C18: Năm | D18: Thời hạn vay
A19: C. NHÂN SỰ & LƯƠNG
A20: Chỉ tiêu | B20: N1 | C20: N2 | D20: N3 | E20: N4 | F20: N5 | G20: N6 | H20: N7 | I20: Lương cơ bản (tr/th)
A21: Giám đốc điều hành | B21: 1 | C21: 1 | D21: 1 | E21: 2 | F21: 2 | G21: 2 | H21: 2 | I21: 14
A22: Nhân sự IT/Kỹ thuật | B22: 2 | C22: 2 | D22: 3 | E22: 4 | F22: 4 | G22: 4 | H22: 4 | I22: 10
A23: Nhân sự vận hành hệ thống | B23: 1 | C23: 1 | D23: 2 | E23: 2 | F23: 2 | G23: 2 | H23: 2 | I23: 8
A24: Nhân sự Marketing | B24: 1 | C24: 1 | D24: 2 | E24: 2 | F24: 3 | G24: 3 | H24: 3 | I24: 6
A25: Nhân sự Finance/Kế toán | B25: 1 | C25: 1 | D25: 1 | E25: 2 | F25: 2 | G25: 3 | H25: 3 | I25: 7
A26: Nhân sự chăm sóc khách hàng | B26: 1 | C26: 2 | D26: 2 | E26: 2 | F26: 2 | G26: 3 | H26: 3 | I26: 5
A27: Tỷ lệ tăng lương hàng năm | B27: 0.05 | C27: Năm | D27: 7%/năm - thị trường IT VN (lạm phát + cạnh tranh nhân tài)
A28: D. GIẢ ĐỊNH DOANH THU
A29: Số doanh nghiệp đối tác (N1/N2/N3/N4/N5) | B29: 8/18/35/60/100/170/220 | C29: DN | D29: N6: 140 DN, N7: 200 DN - tăng trưởng ổn định sau scale
A30: Phí sử dụng app / DN / tháng | B30: 5 | C30: Triệu VND
A31: Tỷ lệ hoa hồng bảo hiểm | B31: 0.15 | C31: Tỷ lệ | D31: Hoa hồng đại lý BH nông nghiệp VN thực tế: 10-20%, dùng 15% | E31: Dự kiến
A32: Tỷ lệ giá trị giao dịch từ DN (trả trước) | B32: 0.05 | C32: Tỷ lệ
A33: Tỷ lệ giá trị giao dịch từ DN (trả sau) | B33: 0.0595 | C33: Tỷ lệ
A34: E. GIẢ ĐỊNH VỐN LƯU ĐỘNG
A35: Khoản phải thu (AR) / Doanh thu | B35: 0.1 | C35: Tỷ lệ | D35: 10% DT chưa thu được
A36: Khoản phải trả (AP) / Chi phí vận hành | B36: 0.1 | C36: Tỷ lệ | D36: 10% CP chưa thanh toán
A37: Số dư tiền mặt tối thiểu (CB) / Doanh thu | B37: 0.02 | C37: Tỷ lệ | D37: 2% DT dự phòng
A38: F. TỶ LỆ CHI PHÍ HOẠT ĐỘNG / DOANH THU
A39: Chi phí hoạt động nền tảng | B39: 0.15 | C39: Tỷ lệ DT | D39: 15% DT - server, API, cloud; tối ưu hóa cloud cost bằng contract dài hạn AWS/GCP
A40: Chi phí Marketing | B40: 0.12 | C40: Tỷ lệ DT | D40: 12% DT - tập trung B2B partnership thay vì paid ads; CAC thấp hơn nhờ referral
...

Sheet 2. Báo cáo Ngân lưu
A1: BÁO CÁO NGÂN LƯU DỰ ÁN - CHAMP MẠNH CHAT (Đơn vị: Triệu VND)
A2: Giai đoạn dự án: 7 năm | WACC: ~14.3% | Năm: 2026-2034
A3: KHOẢN MỤC | B3: Năm 0 (Đầu tư) | C3: Năm 1 | D3: Năm 2 | E3: Năm 3 | F3: Năm 4 | G3: Năm 5 | H3: Năm 6 | I3: Năm 7
A4: I. NGÂN LƯU VÀO (INFLOWS)
A5: 1. Doanh thu phí sử dụng app (từ doanh nghiệp) | B5: - | C5: =C6*C7*12 -> 480 | D5: =D6*D7*12 -> 1080 | E5: =E6*E7*12 -> 2100 | F5: =F6*F7*12 -> 3600 | G5: =G6*G7*12 -> 6000 | H5: =H6*H7*12 -> 10200 | I5: =I6*I7*12 -> 13200
A6: → Số DN đối tác | B6: - | C6: 8 | D6: 18 | E6: 35 | F6: 60 | G6: 100 | H6: 170 | I6: 220
A7: → Phí/DN/tháng (triệu) | B7: - | C7: ='1. Giả định & Thông số'!$B$30 -> 5 | D7: ='1. Giả định & Thông số'!$B$30 -> 5 | E7: ='1. Giả định & Thông số'!$B$30 -> 5 | F7: ='1. Giả định & Thông số'!$B$30 -> 5 | G7: ='1. Giả định & Thông số'!$B$30 -> 5 | H7: ='1. Giả định & Thông số'!$B$30 -> 5 | I7: ='1. Giả định & Thông số'!$B$30 -> 5
A8: 2. Doanh thu hoa hồng - Bảo hiểm nông nghiệp | B8: - | J8: Dự kiến
A9: → Doanh thu bán bảo hiểm | B9: - | J9: Dự kiến
A10: → Tỷ lệ hoa hồng BH | B10: - | J10: Dự kiến
A11: 3. Doanh thu hoa hồng - Doanh nghiệp & Ngân hàng | B11: - | C11: =C12*5%+C13*6% -> 112 | D11: =D12*5%+D13*6% -> 322.56 | E11: =E12*5%+E13*6% -> 823.2 | F11: =F12*5%+F13*6% -> 1848 | G11: =G12*5%+G13*6% -> 3920 | H11: =H12*5%+H13*6% -> 8092 | I11: =I12*5%+I13*6% -> 12320
A12: → Giá trị giao dịch trả trước qua nền tảng (5%) | B12: - | C12: 800 | D12: 2304 | E12: 5880 | F12: 13200 | G12: 28000 | H12: 57800 | I12: 88000
A13: → Giá trị giao dịch trả sau qua nền tảng (6%) | B13: - | C13: 1200 | D13: 3456 | E13: 8820 | F13: 19800 | G13: 42000 | H13: 86700 | I13: 132000
A14: 4. Thu hồi vốn lưu động (cuối dự án - năm 7) | B14: 0 | C14: 0 | D14: 0 | E14: 0 | F14: 0 | G14: 0 | H14: 0 | I14: ='1. Giả định & Thông số'!$B$35*(I5+I8+I11) -> 2552
A15: TỔNG NGÂN LƯU VÀO | B15: 0 | C15: =C5+C8+C11+IF(ISNUMBER(C14),C14,0) -> 592 | D15: =D5+D8+D11+IF(ISNUMBER(D14),D14,0) -> 1402.56 | E15: =E5+E8+E11+IF(ISNUMBER(E14),E14,0) -> 2923.2 | F15: =F5+F8+F11+IF(ISNUMBER(F14),F14,0) -> 5448 | G15: =G5+G8+G11+IF(ISNUMBER(G14),G14,0) -> 9920 | H15: =H5+H8+H11+IF(ISNUMBER(H14),H14,0) -> 18292 | I15: =I5+I8+I11+IF(ISNUMBER(I14),I14,0) -> 28072
A17: II. NGÂN LƯU RA (OUTFLOWS)
A18: A. Chi phí đầu tư ban đầu (năm 0) | B18: ='1. Giả định & Thông số'!$B$4+'1. Giả định & Thông số'!$B$5+'1. Giả định & Thông số'!$B$6+'1. Giả định & Thông số'!$B$7 -> 2590 | C18: - | D18: - | E18: - | F18: - | G18: - | H18: - | I18: -
A19: → Chi phí thành lập DN | B19: ='1. Giả định & Thông số'!$B$4 -> 10 | C19: - | D19: - | E19: - | F19: - | G19: - | H19: - | I19: -
A20: → Chi phí phát triển ứng dụng | B20: ='1. Giả định & Thông số'!$B$5 -> 1800 | C20: - | D20: - | E20: - | F20: - | G20: - | H20: - | I20: -
A21: → Chi phí vật tư, thiết bị | B21: ='1. Giả định & Thông số'!$B$6 -> 180 | C21: - | D21: - | E21: - | F21: - | G21: - | H21: - | I21: -
A22: → Chi phí triển khai & ra mắt sản phẩm | B22: ='1. Giả định & Thông số'!$B$7 -> 600 | C22: - | D22: - | E22: - | F22: - | G22: - | H22: - | I22: -
A23: B. Chi phí nhân sự (tăng lương 5%/năm) | B23: - | C23: ='3. Chi phí chi tiết'!C10 -> 720 | D23: ='3. Chi phí chi tiết'!D10 -> 819 | E23: ='3. Chi phí chi tiết'!E10 -> 1177.47 | F23: ='3. Chi phí chi tiết'!F10 -> 1666.98 | G23: ='3. Chi phí chi tiết'!G10 -> 1837.8455 | H23: ='3. Chi phí chi tiết'!H10 -> 2219.1984 | I23: ='3. Chi phí chi tiết'!I10 -> 2330.1583
A24: → Giám đốc điều hành | B24: - | C24: ='3. Chi phí chi tiết'!C4 -> 168 | D24: ='3. Chi phí chi tiết'!D4 -> 176.4 | E24: ='3. Chi phí chi tiết'!E4 -> 185.22 | F24: ='3. Chi phí chi tiết'!F4 -> 388.962 | G24: ='3. Chi phí chi tiết'!G4 -> 408.4101 | H24: ='3. Chi phí chi tiết'!H4 -> 450.27214 | I24: ='3. Chi phí chi tiết'!I4 -> 472.78574
A25: → Nhân sự IT/Kỹ thuật (×2) | B25: - | C25: ='3. Chi phí chi tiết'!C5 -> 240 | D25: ='3. Chi phí chi tiết'!D5 -> 252 | E25: ='3. Chi phí chi tiết'!E5 -> 396.9 | F25: ='3. Chi phí chi tiết'!F5 -> 555.66 | G25: ='3. Chi phí chi tiết'!G5 -> 583.443 | H25: ='3. Chi phí chi tiết'!H5 -> 643.24591 | I25: ='3. Chi phí chi tiết'!I5 -> 675.4082
A26: → Nhân sự vận hành, Marketing, Finance, CSKH | B26: - | C26: =SUM('3. Chi phí chi tiết'!C6:C9) -> 312 | D26: =SUM('3. Chi phí chi tiết'!D6:D9) -> 390.6 | E26: =SUM('3. Chi phí chi tiết'!E6:E9) -> 595.35 | F26: =SUM('3. Chi phí chi tiết'!F6:F9) -> 722.358 | G26: =SUM('3. Chi phí chi tiết'!G6:G9) -> 845.99235 | H26: =SUM('3. Chi phí chi tiết'!H6:H9) -> 1125.6803 | I26: =SUM('3. Chi phí chi tiết'!I6:I9) -> 1181.9644
A27: C. Chi phí duy trì công nghệ (15% CP app / năm) | B27: - | C27: ='3. Chi phí chi tiết'!C13 -> 270 | D27: ='3. Chi phí chi tiết'!D13 -> 270 | E27: ='3. Chi phí chi tiết'!E13 -> 270 | F27: ='3. Chi phí chi tiết'!F13 -> 270 | G27: ='3. Chi phí chi tiết'!G13 -> 270 | H27: ='3. Chi phí chi tiết'!H13 -> 270 | I27: ='3. Chi phí chi tiết'!I13 -> 270
A28: D. Chi phí hoạt động nền tảng (15% DT) | B28: - | C28: ='3. Chi phí chi tiết'!C14 -> 88.8 | D28: ='3. Chi phí chi tiết'!D14 -> 210.384 | E28: ='3. Chi phí chi tiết'!E14 -> 438.48 | F28: ='3. Chi phí chi tiết'!F14 -> 817.2 | G28: ='3. Chi phí chi tiết'!G14 -> 1488 | H28: ='3. Chi phí chi tiết'!H14 -> 2743.8 | I28: ='3. Chi phí chi tiết'!I14 -> 4210.8
A29: E. Chi phí Marketing (15% DT) | B29: - | C29: ='3. Chi phí chi tiết'!C18 -> 71.04 | D29: ='3. Chi phí chi tiết'!D18 -> 168.3072 | E29: ='3. Chi phí chi tiết'!E18 -> 350.784 | F29: ='3. Chi phí chi tiết'!F18 -> 653.76 | G29: ='3. Chi phí chi tiết'!G18 -> 1190.4 | H29: ='3. Chi phí chi tiết'!H18 -> 2195.04 | I29: ='3. Chi phí chi tiết'!I18 -> 3368.64
A30: F. Chi phí Quản lý & Hành chính (cố định) | B30: - | C30: ='1. Giả định & Thông số'!$B$43 -> 240 | D30: ='1. Giả định & Thông số'!$B$43 -> 240 | E30: ='1. Giả định & Thông số'!$B$43 -> 240 | F30: ='1. Giả định & Thông số'!$B$43 -> 240 | G30: ='1. Giả định & Thông số'!$B$43 -> 240 | H30: ='1. Giả định & Thông số'!$B$43 -> 240 | I30: ='1. Giả định & Thông số'!$B$43 -> 240
A31: G. Chi phí Tài chính & Pháp lý định kỳ | B31: - | C31: ='1. Giả định & Thông số'!$B$44 -> 40 | D31: ='1. Giả định & Thông số'!$B$44 -> 40 | E31: ='1. Giả định & Thông số'!$B$44 -> 40 | F31: ='1. Giả định & Thông số'!$B$44 -> 40 | G31: ='1. Giả định & Thông số'!$B$44 -> 40 | H31: ='1. Giả định & Thông số'!$B$44 -> 40 | I31: ='1. Giả định & Thông số'!$B$44 -> 40
A32: H. Chi phí R&D (12% DT) | B32: - | C32: ='3. Chi phí chi tiết'!C19 -> 59.2 | D32: ='3. Chi phí chi tiết'!D19 -> 140.256 | E32: ='3. Chi phí chi tiết'!E19 -> 292.32 | F32: ='3. Chi phí chi tiết'!F19 -> 544.8 | G32: ='3. Chi phí chi tiết'!G19 -> 992 | H32: ='3. Chi phí chi tiết'!H19 -> 1829.2 | I32: ='3. Chi phí chi tiết'!I19 -> 2807.2
A33: I. Tăng vốn lưu động thuần (ΔNWC) | B33: - | C33: =MAX(0,'1. Giả định & Thông số'!$B$35*C15) -> 59.2 | D33: =MAX(0,'1. Giả định & Thông số'!$B$35*(D15-C15)) -> 81.056 | E33: =MAX(0,'1. Giả định & Thông số'!$B$35*(E15-D15)) -> 152.064 | F33: =MAX(0,'1. Giả định & Thông số'!$B$35*(F15-E15)) -> 252.48 | G33: =MAX(0,'1. Giả định & Thông số'!$B$35*(G15-F15)) -> 447.2 | H33: =MAX(0,'1. Giả định & Thông số'!$B$35*(H15-G15)) -> 837.2 | I33: =MAX(0,'1. Giả định & Thông số'!$B$35*(I15-H15)) -> 978
A34: → ΔAR (khoản phải thu tăng thêm) | B34: - | C34: =MAX(0,'1. Giả định & Thông số'!$B$35*C15) -> 59.2 | D34: =MAX(0,'1. Giả định & Thông số'!$B$35*(D15-C15)) -> 81.056 | E34: =MAX(0,'1. Giả định & Thông số'!$B$35*(E15-D15)) -> 152.064 | F34: =MAX(0,'1. Giả định & Thông số'!$B$35*(F15-E15)) -> 252.48 | G34: =MAX(0,'1. Giả định & Thông số'!$B$35*(G15-F15)) -> 447.2 | H34: =H33 -> 837.2 | I34: =I33 -> 978
A35: J. Thuế TNDN (20% lợi nhuận chịu thuế) | B35: - | C35: =MAX(0,'1. Giả định & Thông số'!$B$16*'4. Báo cáo Thu nhập'!C11) -> 0 | D35: =MAX(0,'1. Giả định & Thông số'!$B$16*'4. Báo cáo Thu nhập'!D11) -> 0 | E35: =MAX(0,'1. Giả định & Thông số'!$B$16*'4. Báo cáo Thu nhập'!E11) -> 0 | F35: =MAX(0,'1. Giả định & Thông số'!$B$16*'4. Báo cáo Thu nhập'!F11) -> 175.91972 | G35: =MAX(0,'1. Giả định & Thông số'!$B$16*'4. Báo cáo Thu nhập'!G11) -> 710.22377 | H35: =MAX(0,'1. Giả định & Thông số'!$B$16*'4. Báo cáo Thu nhập'!H11) -> 1694.3809 | I35: =MAX(0,'1. Giả định & Thông số'!$B$16*'4. Báo cáo Thu nhập'!I11) -> 2904.4689
A36: TỔNG NGÂN LƯU RA | B36: ='1. Giả định & Thông số'!$B$4+'1. Giả định & Thông số'!$B$5+'1. Giả định & Thông số'!$B$6+'1. Giả định & Thông số'!$B$7 -> 2590 | C36: =C23+C27+C28+C29+C30+C31+C32+C33+C35 -> 1548.24 | D36: =D23+D27+D28+D29+D30+D31+D32+D33+D35 -> 1969.0032 | E36: =E23+E27+E28+E29+E30+E31+E32+E33+E35 -> 2961.118 | F36: =F23+F27+F28+F29+F30+F31+F32+F33+F35 -> 4661.1397 | G36: =G23+G27+G28+G29+G30+G31+G32+G33+G35 -> 7215.6692 | H36: =H23+H27+H28+H29+H30+H31+H32+H33+H35 -> 12068.819 | I36: =I23+I27+I28+I29+I30+I31+I32+I33+I35 -> 17149.267
A38: III. NGÂN LƯU RÒNG TRƯỚC TÀI TRỢ (NCF - TIPV)
A39: Ngân lưu ròng TIPV (= Inflow − Outflow) | B39: =-B36 -> -2590 | C39: =C15-C36 -> -956.24 | D39: =D15-D36 -> -566.4432 | E39: =E15-E36 -> -37.918 | F39: =F15-F36 -> 786.86028 | G39: =G15-G36 -> 2704.3308 | H39: =H15-H36 -> 6223.1807 | I39: =I15-I36 -> 10922.733
A40: Ngân lưu ròng TIPV lũy kế | B40: =B39 -> -2590 | C40: =B40+C39 -> -3546.24 | D40: =C40+D39 -> -4112.6832 | E40: =D40+E39 -> -4150.6012 | F40: =E40+F39 -> -3363.7409 | G40: =F40+G39 -> -659.41014 | H40: =G40+H39 -> 5563.7706 | I40: =H40+I39 -> 16486.503
A42: IV. TÀI TRỢ VỐN VAY & LỊCH TRẢ NỢ
A43: Giải ngân vốn vay (năm 0) | B43: ='1. Giả định & Thông số'!$B$12 -> 1036 | C43: - | D43: - | E43: - | F43: - | G43: - | H43: - | I43: -
...

Sheet 3. Chi phí chi tiết
A1: BẢNG CHI PHÍ VẬN HÀNH CHI TIẾT - CHAMP MẠNH CHAT (Đơn vị: Triệu VND)
A2: KHOẢN MỤC | B2: Năm 0 (Đầu tư) | C2: Năm 1 | D2: Năm 2 | E2: Năm 3 | F2: Năm 4 | G2: Năm 5 | H2: Năm 6 | I2: Năm 7
A3: I. CHI PHÍ NHÂN SỰ
A4: Giám đốc điều hành | B4: - | C4: ='1. Giả định & Thông số'!$B$21*'1. Giả định & Thông số'!$I$21*12*(1+'1. Giả định & Thông số'!$B$27)^0 -> 168 | D4: ='1. Giả định & Thông số'!$C$21*'1. Giả định & Thông số'!$I$21*12*(1+'1. Giả định & Thông số'!$B$27)^1 -> 176.4 | E4: ='1. Giả định & Thông số'!$D$21*'1. Giả định & Thông số'!$I$21*12*(1+'1. Giả định & Thông số'!$B$27)^2 -> 185.22 | F4: ='1. Giả định & Thông số'!$E$21*'1. Giả định & Thông số'!$I$21*12*(1+'1. Giả định & Thông số'!$B$27)^3 -> 388.962 | G4: ='1. Giả định & Thông số'!$F$21*'1. Giả định & Thông số'!$I$21*12*(1+'1. Giả định & Thông số'!$B$27)^4 -> 408.4101 | H4: ='1. Giả định & Thông số'!$G$21*'1. Giả định & Thông số'!$I$21*12*(1+'1. Giả định & Thông số'!$B$27)^6 -> 450.27214 | I4: ='1. Giả định & Thông số'!$H$21*'1. Giả định & Thông số'!$I$21*12*(1+'1. Giả định & Thông số'!$B$27)^7 -> 472.78574
A5: Nhân sự IT/Kỹ thuật | B5: - | C5: ='1. Giả định & Thông số'!$B$22*'1. Giả định & Thông số'!$I$22*12*(1+'1. Giả định & Thông số'!$B$27)^0 -> 240 | D5: ='1. Giả định & Thông số'!$C$22*'1. Giả định & Thông số'!$I$22*12*(1+'1. Giả định & Thông số'!$B$27)^1 -> 252 | E5: ='1. Giả định & Thông số'!$D$22*'1. Giả định & Thông số'!$I$22*12*(1+'1. Giả định & Thông số'!$B$27)^2 -> 396.9 | F5: ='1. Giả định & Thông số'!$E$22*'1. Giả định & Thông số'!$I$22*12*(1+'1. Giả định & Thông số'!$B$27)^3 -> 555.66 | G5: ='1. Giả định & Thông số'!$F$22*'1. Giả định & Thông số'!$I$22*12*(1+'1. Giả định & Thông số'!$B$27)^4 -> 583.443 | H5: ='1. Giả định & Thông số'!$G$22*'1. Giả định & Thông số'!$I$22*12*(1+'1. Giả định & Thông số'!$B$27)^6 -> 643.24591 | I5: ='1. Giả định & Thông số'!$H$22*'1. Giả định & Thông số'!$I$22*12*(1+'1. Giả định & Thông số'!$B$27)^7 -> 675.4082
A6: Nhân sự vận hành | B6: - | C6: ='1. Giả định & Thông số'!$B$23*'1. Giả định & Thông số'!$I$23*12*(1+'1. Giả định & Thông số'!$B$27)^0 -> 96 | D6: ='1. Giả định & Thông số'!$C$23*'1. Giả định & Thông số'!$I$23*12*(1+'1. Giả định & Thông số'!$B$27)^1 -> 100.8 | E6: ='1. Giả định & Thông số'!$D$23*'1. Giả định & Thông số'!$I$23*12*(1+'1. Giả định & Thông số'!$B$27)^2 -> 211.68 | F6: ='1. Giả định & Thông số'!$E$23*'1. Giả định & Thông số'!$I$23*12*(1+'1. Giả định & Thông số'!$B$27)^3 -> 222.264 | G6: ='1. Giả định & Thông số'!$F$23*'1. Giả định & Thông số'!$I$23*12*(1+'1. Giả định & Thông số'!$B$27)^4 -> 233.3772 | H6: ='1. Giả định & Thông số'!$G$23*'1. Giả định & Thông số'!$I$23*12*(1+'1. Giả định & Thông số'!$B$27)^6 -> 257.29836 | I6: ='1. Giả định & Thông số'!$H$23*'1. Giả định & Thông số'!$I$23*12*(1+'1. Giả định & Thông số'!$B$27)^7 -> 270.16328
A7: Nhân sự Marketing | B7: - | C7: ='1. Giả định & Thông số'!$B$24*'1. Giả định & Thông số'!$I$24*12*(1+'1. Giả định & Thông số'!$B$27)^0 -> 72 | D7: ='1. Giả định & Thông số'!$C$24*'1. Giả định & Thông số'!$I$24*12*(1+'1. Giả định & Thông số'!$B$27)^1 -> 75.6 | E7: ='1. Giả định & Thông số'!$D$24*'1. Giả định & Thông số'!$I$24*12*(1+'1. Giả định & Thông số'!$B$27)^2 -> 158.76 | F7: ='1. Giả định & Thông số'!$E$24*'1. Giả định & Thông số'!$I$24*12*(1+'1. Giả định & Thông số'!$B$27)^3 -> 166.698 | G7: ='1. Giả định & Thông số'!$F$24*'1. Giả định & Thông số'!$I$24*12*(1+'1. Giả định & Thông số'!$B$27)^4 -> 262.54935 | H7: ='1. Giả định & Thông số'!$G$24*'1. Giả định & Thông số'!$I$24*12*(1+'1. Giả định & Thông số'!$B$27)^6 -> 289.46066 | I7: ='1. Giả định & Thông số'!$H$24*'1. Giả định & Thông số'!$I$24*12*(1+'1. Giả định & Thông số'!$B$27)^7 -> 303.93369
A8: Nhân sự Finance/Kế toán | B8: - | C8: ='1. Giả định & Thông số'!$B$25*'1. Giả định & Thông số'!$I$25*12*(1+'1. Giả định & Thông số'!$B$27)^0 -> 84 | D8: ='1. Giả định & Thông số'!$C$25*'1. Giả định & Thông số'!$I$25*12*(1+'1. Giả định & Thông số'!$B$27)^1 -> 88.2 | E8: ='1. Giả định & Thông số'!$D$25*'1. Giả định & Thông số'!$I$25*12*(1+'1. Giả định & Thông số'!$B$27)^2 -> 92.61 | F8: ='1. Giả định & Thông số'!$E$25*'1. Giả định & Thông số'!$I$25*12*(1+'1. Giả định & Thông số'!$B$27)^3 -> 194.481 | G8: ='1. Giả định & Thông số'!$F$25*'1. Giả định & Thông số'!$I$25*12*(1+'1. Giả định & Thông số'!$B$27)^4 -> 204.20505 | H8: ='1. Giả định & Thông số'!$G$25*'1. Giả định & Thông số'!$I$25*12*(1+'1. Giả định & Thông số'!$B$27)^6 -> 337.7041 | I8: ='1. Giả định & Thông số'!$H$25*'1. Giả định & Thông số'!$I$25*12*(1+'1. Giả định & Thông số'!$B$27)^7 -> 354.58931
A9: Nhân sự CSKH | B9: - | C9: ='1. Giả định & Thông số'!$B$26*'1. Giả định & Thông số'!$I$26*12*(1+'1. Giả định & Thông số'!$B$27)^0 -> 60 | D9: ='1. Giả định & Thông số'!$C$26*'1. Giả định & Thông số'!$I$26*12*(1+'1. Giả định & Thông số'!$B$27)^1 -> 126 | E9: ='1. Giả định & Thông số'!$D$26*'1. Giả định & Thông số'!$I$26*12*(1+'1. Giả định & Thông số'!$B$27)^2 -> 132.3 | F9: ='1. Giả định & Thông số'!$E$26*'1. Giả định & Thông số'!$I$26*12*(1+'1. Giả định & Thông số'!$B$27)^3 -> 138.915 | G9: ='1. Giả định & Thông số'!$F$26*'1. Giả định & Thông số'!$I$26*12*(1+'1. Giả định & Thông số'!$B$27)^4 -> 145.86075 | H9: ='1. Giả định & Thông số'!$G$26*'1. Giả định & Thông số'!$I$26*12*(1+'1. Giả định & Thông số'!$B$27)^6 -> 241.21722 | I9: ='1. Giả định & Thông số'!$H$26*'1. Giả định & Thông số'!$I$26*12*(1+'1. Giả định & Thông số'!$B$27)^7 -> 253.27808
A10: TỔNG NHÂN SỰ | B10: - | C10: =SUM(C4:C9) -> 720 | D10: =SUM(D4:D9) -> 819 | E10: =SUM(E4:E9) -> 1177.47 | F10: =SUM(F4:F9) -> 1666.98 | G10: =SUM(G4:G9) -> 1837.8455 | H10: =SUM(H4:H9) -> 2219.1984 | I10: =SUM(I4:I9) -> 2330.1583
A12: II. CHI PHÍ CÔNG NGHỆ & HẠ TẦNG
A13: Duy trì công nghệ (20% × 2,200 triệu) | B13: - | C13: ='1. Giả định & Thông số'!$B$42*'1. Giả định & Thông số'!$B$5 -> 270 | D13: ='1. Giả định & Thông số'!$B$42*'1. Giả định & Thông số'!$B$5 -> 270 | E13: ='1. Giả định & Thông số'!$B$42*'1. Giả định & Thông số'!$B$5 -> 270 | F13: ='1. Giả định & Thông số'!$B$42*'1. Giả định & Thông số'!$B$5 -> 270 | G13: ='1. Giả định & Thông số'!$B$42*'1. Giả định & Thông số'!$B$5 -> 270 | H13: ='1. Giả định & Thông số'!$B$42*'1. Giả định & Thông số'!$B$5 -> 270 | I13: ='1. Giả định & Thông số'!$B$42*'1. Giả định & Thông số'!$B$5 -> 270
A14: Hoạt động nền tảng (server, API, IoT, data) | B14: - | C14: ='1. Giả định & Thông số'!$B$39*'2. Báo cáo Ngân lưu'!C15 -> 88.8 | D14: ='1. Giả định & Thông số'!$B$39*'2. Báo cáo Ngân lưu'!D15 -> 210.384 | E14: ='1. Giả định & Thông số'!$B$39*'2. Báo cáo Ngân lưu'!E15 -> 438.48 | F14: ='1. Giả định & Thông số'!$B$39*'2. Báo cáo Ngân lưu'!F15 -> 817.2 | G14: ='1. Giả định & Thông số'!$B$39*'2. Báo cáo Ngân lưu'!G15 -> 1488 | H14: ='1. Giả định & Thông số'!$B$39*'2. Báo cáo Ngân lưu'!H15 -> 2743.8 | I14: ='1. Giả định & Thông số'!$B$39*'2. Báo cáo Ngân lưu'!I15 -> 4210.8
A15: TỔNG CÔNG NGHỆ & HẠ TẦNG | B15: - | C15: =C13+C14 -> 358.8 | D15: =D13+D14 -> 480.384 | E15: =E13+E14 -> 708.48 | F15: =F13+F14 -> 1087.2 | G15: =G13+G14 -> 1758 | H15: =H13+H14 -> 3013.8 | I15: =I13+I14 -> 4480.8
A17: III. CHI PHÍ MARKETING & R&D
A18: Marketing (15% DT) | B18: - | C18: ='1. Giả định & Thông số'!$B$40*'2. Báo cáo Ngân lưu'!C15 -> 71.04 | D18: ='1. Giả định & Thông số'!$B$40*'2. Báo cáo Ngân lưu'!D15 -> 168.3072 | E18: ='1. Giả định & Thông số'!$B$40*'2. Báo cáo Ngân lưu'!E15 -> 350.784 | F18: ='1. Giả định & Thông số'!$B$40*'2. Báo cáo Ngân lưu'!F15 -> 653.76 | G18: ='1. Giả định & Thông số'!$B$40*'2. Báo cáo Ngân lưu'!G15 -> 1190.4 | H18: ='1. Giả định & Thông số'!$B$40*'2. Báo cáo Ngân lưu'!H15 -> 2195.04 | I18: ='1. Giả định & Thông số'!$B$40*'2. Báo cáo Ngân lưu'!I15 -> 3368.64
A19: R&D (12% DT) | B19: - | C19: ='1. Giả định & Thông số'!$B$41*'2. Báo cáo Ngân lưu'!C15 -> 59.2 | D19: ='1. Giả định & Thông số'!$B$41*'2. Báo cáo Ngân lưu'!D15 -> 140.256 | E19: ='1. Giả định & Thông số'!$B$41*'2. Báo cáo Ngân lưu'!E15 -> 292.32 | F19: ='1. Giả định & Thông số'!$B$41*'2. Báo cáo Ngân lưu'!F15 -> 544.8 | G19: ='1. Giả định & Thông số'!$B$41*'2. Báo cáo Ngân lưu'!G15 -> 992 | H19: ='1. Giả định & Thông số'!$B$41*'2. Báo cáo Ngân lưu'!H15 -> 1829.2 | I19: ='1. Giả định & Thông số'!$B$41*'2. Báo cáo Ngân lưu'!I15 -> 2807.2
A20: TỔNG MKT & R&D | B20: - | C20: =C18+C19 -> 130.24 | D20: =D18+D19 -> 308.5632 | E20: =E18+E19 -> 643.104 | F20: =F18+F19 -> 1198.56 | G20: =G18+G19 -> 2182.4 | H20: =H18+H19 -> 4024.24 | I20: =I18+I19 -> 6175.84
A22: IV. CHI PHÍ CỐ ĐỊNH
A23: Quản lý & Hành chính (VP, điện, nước…) | B23: - | C23: ='1. Giả định & Thông số'!$B$43 -> 240 | D23: ='1. Giả định & Thông số'!$B$43 -> 240 | E23: ='1. Giả định & Thông số'!$B$43 -> 240 | F23: ='1. Giả định & Thông số'!$B$43 -> 240 | G23: ='1. Giả định & Thông số'!$B$43 -> 240 | H23: ='1. Giả định & Thông số'!$B$43 -> 240 | I23: ='1. Giả định & Thông số'!$B$43 -> 240
A24: Tài chính & Pháp lý định kỳ | B24: - | C24: ='1. Giả định & Thông số'!$B$44 -> 40 | D24: ='1. Giả định & Thông số'!$B$44 -> 40 | E24: ='1. Giả định & Thông số'!$B$44 -> 40 | F24: ='1. Giả định & Thông số'!$B$44 -> 40 | G24: ='1. Giả định & Thông số'!$B$44 -> 40 | H24: ='1. Giả định & Thông số'!$B$44 -> 40 | I24: ='1. Giả định & Thông số'!$B$44 -> 40
A25: TỔNG CHI PHÍ CỐ ĐỊNH | B25: - | C25: =C23+C24 -> 280 | D25: =D23+D24 -> 280 | E25: =E23+E24 -> 280 | F25: =F23+F24 -> 280 | G25: =G23+G24 -> 280 | H25: =H23+H24 -> 280 | I25: =I23+I24 -> 280
A27: TỔNG CHI PHÍ VẬN HÀNH | B27: - | C27: =C10+C15+C20+C25 -> 1489.04 | D27: =D10+D15+D20+D25 -> 1887.9472 | E27: =E10+E15+E20+E25 -> 2809.054 | F27: =F10+F15+F20+F25 -> 4232.74 | G27: =G10+G15+G20+G25 -> 6058.2455 | H27: =H10+H15+H20+H25 -> 9537.2384 | I27: =I10+I15+I20+I25 -> 13266.798

Sheet 5. Lịch trả nợ
A1: LỊCH TRẢ NỢ - CHAMP MẠNH CHAT (Đơn vị: Triệu VND)
A2: KHOẢN MỤC | B2: Năm 0 (Đầu tư) | C2: Năm 1 | D2: Năm 2 | E2: Năm 3 | F2: Năm 4 | G2: Năm 5 | H2: Năm 6 | I2: Năm 7
A3: Nguồn vốn vay: 957 triệu | Lãi suất: 11%/năm | Thời hạn: 5 năm | Loại: Annuity | Năm 6-7: Đã hết nợ
A4: Dư nợ đầu kỳ | B4: - | C4: ='1. Giả định & Thông số'!$B$12 -> 1036 | D4: =C8 -> 869.64916 | E4: =D8 -> 684.99973 | F4: =E8 -> 480.03886 | G4: =F8 -> 252.53229 | H4: 0 | I4: 0
A5: Lãi phát sinh (10%) | B5: - | C5: =C4*'1. Giả định & Thông số'!$B$14 -> 113.96 | D5: =D4*'1. Giả định & Thông số'!$B$14 -> 95.661408 | E5: =E4*'1. Giả định & Thông số'!$B$14 -> 75.34997 | F5: =F4*'1. Giả định & Thông số'!$B$14 -> 52.804274 | G5: =G4*'1. Giả định & Thông số'!$B$14 -> 27.778552 | H5: 0 | I5: 0
A6: Trả nợ gốc | B6: - | C6: =C7-C5 -> 166.35084 | D6: =D7-D5 -> 184.64943 | E6: =E7-E5 -> 204.96087 | F6: =F7-F5 -> 227.50657 | G6: =G7-G5 -> 252.53229 | H6: 0 | I6: 0
A7: TỔNG THANH TOÁN | B7: - | C7: ='1. Giả định & Thông số'!$B$12*'1. Giả định & Thông số'!$B$14/(1-(1+'1. Giả định & Thông số'!$B$14)^(-'1. Giả định & Thông số'!$B$18)) -> 280.31084 | D7: ='1. Giả định & Thông số'!$B$12*'1. Giả định & Thông số'!$B$14/(1-(1+'1. Giả định & Thông số'!$B$14)^(-'1. Giả định & Thông số'!$B$18)) -> 280.31084 | E7: ='1. Giả định & Thông số'!$B$12*'1. Giả định & Thông số'!$B$14/(1-(1+'1. Giả định & Thông số'!$B$14)^(-'1. Giả định & Thông số'!$B$18)) -> 280.31084 | F7: ='1. Giả định & Thông số'!$B$12*'1. Giả định & Thông số'!$B$14/(1-(1+'1. Giả định & Thông số'!$B$14)^(-'1. Giả định & Thông số'!$B$18)) -> 280.31084 | G7: ='1. Giả định & Thông số'!$B$12*'1. Giả định & Thông số'!$B$14/(1-(1+'1. Giả định & Thông số'!$B$14)^(-'1. Giả định & Thông số'!$B$18)) -> 280.31084 | H7: 0 | I7: 0
A8: Dư nợ cuối kỳ | B8: ='1. Giả định & Thông số'!$B$12 -> 1036 | C8: =C4-C6 -> 869.64916 | D8: =D4-D6 -> 684.99973 | E8: =E4-E6 -> 480.03886 | F8: =F4-F6 -> 252.53229 | G8: =G4-G6 -> 0 | H8: 0 | I8: 0

Sheet 4. Báo cáo Thu nhập
A1: BÁO CÁO THU NHẬP - CHAMP MẠNH CHAT (Đơn vị: Triệu VND)
A2: KHOẢN MỤC | B2: Năm 0 (Đầu tư) | C2: Năm 1 | D2: Năm 2 | E2: Năm 3 | F2: Năm 4 | G2: Năm 5 | H2: Năm 6 | I2: Năm 7
A3: TỔNG DOANH THU | B3: - | C3: ='2. Báo cáo Ngân lưu'!C15 -> 592 | D3: ='2. Báo cáo Ngân lưu'!D15 -> 1402.56 | E3: ='2. Báo cáo Ngân lưu'!E15 -> 2923.2 | F3: ='2. Báo cáo Ngân lưu'!F15 -> 5448 | G3: ='2. Báo cáo Ngân lưu'!G15 -> 9920 | H3: ='2. Báo cáo Ngân lưu'!H15 -> 18292 | I3: ='2. Báo cáo Ngân lưu'!I15 -> 28072
A4: Phí sử dụng app | B4: - | C4: ='2. Báo cáo Ngân lưu'!C5 -> 480 | D4: ='2. Báo cáo Ngân lưu'!D5 -> 1080 | E4: ='2. Báo cáo Ngân lưu'!E5 -> 2100 | F4: ='2. Báo cáo Ngân lưu'!F5 -> 3600 | G4: ='2. Báo cáo Ngân lưu'!G5 -> 6000 | H4: ='2. Báo cáo Ngân lưu'!H5 -> 10200 | I4: ='2. Báo cáo Ngân lưu'!I5 -> 13200
A5: Hoa hồng bảo hiểm | B5: - | C5: ='2. Báo cáo Ngân lưu'!C8 | D5: ='2. Báo cáo Ngân lưu'!D8 | E5: ='2. Báo cáo Ngân lưu'!E8 | F5: ='2. Báo cáo Ngân lưu'!F8 | G5: ='2. Báo cáo Ngân lưu'!G8 | H5: ='2. Báo cáo Ngân lưu'!H8 | I5: ='2. Báo cáo Ngân lưu'!I8
A6: Hoa hồng DN & NH | B6: - | C6: ='2. Báo cáo Ngân lưu'!C11 -> 112 | D6: ='2. Báo cáo Ngân lưu'!D11 -> 322.56 | E6: ='2. Báo cáo Ngân lưu'!E11 -> 823.2 | F6: ='2. Báo cáo Ngân lưu'!F11 -> 1848 | G6: ='2. Báo cáo Ngân lưu'!G11 -> 3920 | H6: ='2. Báo cáo Ngân lưu'!H11 -> 8092 | I6: ='2. Báo cáo Ngân lưu'!I11 -> 12320
A7: (-) Chi phí vận hành | B7: - | C7: ='3. Chi phí chi tiết'!C27 -> 1489.04 | D7: ='3. Chi phí chi tiết'!D27 -> 1887.9472 | E7: ='3. Chi phí chi tiết'!E27 -> 2809.054 | F7: ='3. Chi phí chi tiết'!F27 -> 4232.74 | G7: ='3. Chi phí chi tiết'!G27 -> 6058.2455 | H7: ='3. Chi phí chi tiết'!H27 -> 9537.2384 | I7: ='3. Chi phí chi tiết'!I27 -> 13266.798
A8: (-) Khấu hao tài sản | B8: - | C8: ='7. Lạm phát & Khấu hao'!D43 -> 492.85714 | D8: ='7. Lạm phát & Khấu hao'!E43 -> 482.85714 | E8: ='7. Lạm phát & Khấu hao'!F43 -> 482.85714 | F8: ='7. Lạm phát & Khấu hao'!G43 -> 282.85714 | G8: ='7. Lạm phát & Khấu hao'!H43 -> 282.85714 | H8: ='7. Lạm phát & Khấu hao'!I43 -> 282.85714 | I8: ='7. Lạm phát & Khấu hao'!J43 -> 282.85714
A9: EBIT | B9: - | C9: =C3-C7-C8 -> -1389.8971 | D9: =D3-D7-D8 -> -968.24434 | E9: =E3-E7-E8 -> -368.71114 | F9: =F3-F7-F8 -> 932.40286 | G9: =G3-G7-G8 -> 3578.8974 | H9: =H3-H7-H8 -> 8471.9045 | I9: =I3-I7-I8 -> 14522.345
A10: (-) Lãi vay | B10: - | C10: =-'2. Báo cáo Ngân lưu'!C45 -> -113.96 | D10: =-'2. Báo cáo Ngân lưu'!D45 -> -95.661408 | E10: =-'2. Báo cáo Ngân lưu'!E45 -> -75.34997 | F10: =-'2. Báo cáo Ngân lưu'!F45 -> -52.804274 | G10: =-'2. Báo cáo Ngân lưu'!G45 -> -27.778552 | H10: 0 | I10: 0
A11: LỢI NHUẬN TRƯỚC THUẾ (EBT) | B11: - | C11: =C9+C10 -> -1503.8571 | D11: =D9+D10 -> -1063.9057 | E11: =E9+E10 -> -444.06111 | F11: =F9+F10 -> 879.59858 | G11: =G9+G10 -> 3551.1189 | H11: =H9+H10 -> 8471.9045 | I11: =I9+I10 -> 14522.345
A12: (-) Thuế TNDN (20%) | B12: - | C12: =-MAX(0,'1. Giả định & Thông số'!$B$16*C11) -> 0 | D12: =-MAX(0,'1. Giả định & Thông số'!$B$16*D11) -> 0 | E12: =-MAX(0,'1. Giả định & Thông số'!$B$16*E11) -> 0 | F12: =-MAX(0,'1. Giả định & Thông số'!$B$16*F11) -> -175.91972 | G12: =-MAX(0,'1. Giả định & Thông số'!$B$16*G11) -> -710.22377 | H12: =-MAX(0,'1. Giả định & Thông số'!$B$16*H11) -> -1694.3809 | I12: =-MAX(0,'1. Giả định & Thông số'!$B$16*I11) -> -2904.4689
A13: THU NHẬP RÒNG (NI) | B13: - | C13: =C11+C12 -> -1503.8571 | D13: =D11+D12 -> -1063.9057 | E13: =E11+E12 -> -444.06111 | F13: =F11+F12 -> 703.67887 | G13: =G11+G12 -> 2840.8951 | H13: =H11+H12 -> 6777.5236 | I13: =I11+I12 -> 11617.876
A14: Biên lợi nhuận ròng (%) | B14: - | C14: =IF(C3>0,C13/C3,"N/A") -> -2.5402992 | D14: =IF(D3>0,D13/D3,"N/A") -> -0.75854562 | E14: =IF(E3>0,E13/E3,"N/A") -> -0.15190925 | F14: =IF(F3>0,F13/F3,"N/A") -> 0.12916279 | G14: =IF(G3>0,G13/G3,"N/A") -> 0.28638055 | H14: =IF(H3>0,H13/H3,"N/A") -> 0.37051846 | I14: =IF(I3>0,I13/I3,"N/A") -> 0.41385992

Sheet 6. Đánh Giá Tài Chính
A1: CHAMP MẠNH CHAT - ĐÁNH GIÁ HIỆU QUẢ TÀI CHÍNH DỰ ÁN
A2: Đơn vị: Triệu VND | Quan điểm: Chủ sở hữu (EPV) | Năm tính: 2026-2034 (7 năm)
A3: CHỈ TIÊU | B3: GIÁ TRỊ | C3: KẾT QUẢ / ĐÁNH GIÁ | D3: NHẬN XÉT CHI TIẾT
A4: A. CÁC CHỈ TIÊU TÀI CHÍNH CHÍNH (QUAN ĐIỂM VỐN CHỦ SỞ HỮU - EPV)
A5: NPV - Giá trị hiện tại thuần (Net Present Value) | B5: ='2. Báo cáo Ngân lưu'!B62 -> 5109.6787 | C5: =IF(B5>0," NPV > 0 → Dự án khả thi tạo giá trị","NPV < 0 → Cần xem xét lại") -> NPV > 0 → Dự án khả thi tạo giá trị | D5: NPV > 0: Dự án tạo ra giá trị vượt trên chi phí vốn (WACC).
A6: IRR - Tỷ suất sinh lời nội bộ (Internal Rate of Return) | B6: ='2. Báo cáo Ngân lưu'!B63 -> 0.34949649 | C6: =IF(ISNUMBER(B6),IF(B6>'1. Giả định & Thông số'!$B$17," IRR > WACC → Dự án sinh lợi vượt chi phí vốn","⚠ IRR < WACC → Cần xem xét lại"),"N/A") -> IRR > WACC → Dự án sinh lợi vượt chi phí vốn | D6: IRR là lãi suất làm NPV = 0. Nếu IRR > WACC (14.32%), dự án sinh lợi vượt chi phí vốn. IRR 36.64% >> WACC 14.32% → Dự án tạo ra giá trị vượt trội. Vòng đời 7 năm (2026-2034).
A7: MIRR - IRR điều chỉnh (Modified IRR, tái đầu tư = WACC) | B7: =IFERROR(MIRR('2. Báo cáo Ngân lưu'!B54:I54,'1. Giả định & Thông số'!$B$17,'1. Giả định & Thông số'!$B$17),"N/A") -> 0.30018147 | C7: =IF(ISNUMBER(B7),IF(B7>'1. Giả định & Thông số'!$B$17," MIRR > WACC → Khả thi","⚠ MIRR < WACC → Xem lại"),"N/A") -> MIRR > WACC → Khả thi | D7: MIRR thực tế hơn IRR vì giả định tái đầu tư dòng tiền dương ở mức WACC (không phải IRR). Phù hợp đánh giá dự án startup giai đoạn đầu thua lỗ.
A8: BCR - Tỷ số lợi ích / chi phí (Benefit-Cost Ratio) | B8: =('2. Báo cáo Ngân lưu'!B62 + ABS('2. Báo cáo Ngân lưu'!B54)) / ABS('2. Báo cáo Ngân lưu'!B54) -> 4.2880815 | C8: =IF(B8>=1," BCR ≥ 1 → Lợi ích vượt chi phí"," BCR < 1 → Chi phí > lợi ích") -> BCR ≥ 1 → Lợi ích vượt chi phí | D8: BCR = (NPV + Equity ban đầu) / Equity ban đầu. BCR > 1 = mỗi đồng vốn thu về nhiều hơn 1 đồng (đã chiết khấu).
A9: EAB - Lợi ích đều quy năm (Equivalent Annual Benefit) | B9: =B5*'1. Giả định & Thông số'!$B$17/(1-(1+'1. Giả định & Thông số'!$B$17)^(-7)) -> 1203.211 | C9: =IF(B9>0," EAB > 0 → Dự án có lợi nhuận hàng năm"," EAB ≤ 0") -> EAB > 0 → Dự án có lợi nhuận hàng năm | D9: EAB phân bổ đều NPV thành lợi ích năm bình quân trong suốt vòng đời dự án. Giúp so sánh các dự án có thời gian khác nhau.
A10: PP - Thời gian hoàn vốn (Payback Period, không chiết khấu) | B10: ='2. Báo cáo Ngân lưu'!B65 -> 5.16
A11: DPP - Thời gian hoàn vốn chiết khấu (Discounted Payback Period) | B11: Năm 5-6 (chiết khấu) | C11: NCF_EPV chiết khấu lũy kế dương từ năm 5-6 → Phù hợp startup B2B fintech 7 năm | D11: DPP = thời gian hoàn vốn tính trên dòng tiền đã chiết khấu → chặt chẽ hơn PP thông thường. Startup fintech giai đoạn đầu thường DPP dài hơn PP 1-2 năm.
A12: WACC - Chi phí vốn bình quân gia quyền | B12: ='1. Giả định & Thông số'!$B$17 -> 0.1432 | C12: ='1. Giả định & Thông số'!B20&" = Re×E/V + Rd×(1-T)×D/V" -> N1 = Re×E/V + Rd×(1-T)×D/V | D12: Re=18% × E/V=60% + Rd=11% × (1−20%) × D/V=40% = 18%×0.6 + 8.8%×0.4 = 10.8%+3.52% = 14.32%. Là ngưỡng tối thiểu IRR phải vượt qua để dự án tạo giá trị.
A14: B. PHÂN TÍCH ĐỘ NHẠY (SENSITIVITY ANALYSIS) - NPV THEO KỊCH BẢN DOANH THU
A15: KỊCH BẢN | B15: HỆ SỐ ĐIỀU CHỈNH DOANH THU | C15: NPV ƯỚC TÍNH (Tr.VND) | D15: NHẬN XÉT
A16: Bi quan - Tăng trưởng chậm (50% DT) | B16: {=NPV('1. Giả định & Thông số'!B17,'2. Báo cáo Ngân lưu'!C59:I59)*0.5+'2. Báo cáo Ngân lưu'!B54} -> -478.38423 | C16: =IF(B16>0,"Khả thi"," Không khả thi") -> Không khả thi | D16: Thị trường fintech nông nghiệp cạnh tranh cao
A17: Thận trọng - Dưới kỳ vọng (75% DT) | B17: {=NPV('1. Giả định & Thông số'!B17,'2. Báo cáo Ngân lưu'!C59:I59)*0.75+'2. Báo cáo Ngân lưu'!B54} -> 59.423656 | C17: =IF(B17>0," Khả thi"," Không khả thi") -> Khả thi | D17: DN onboarding chậm hơn kế hoạch, một số hợp đồng bị trì hoãn
A18: Cơ sở - Đúng kế hoạch (100% DT) | B18: ='2. Báo cáo Ngân lưu'!B62 -> 5109.6787 | C18: =IF(B18>0," Khả thi"," Không khả thi") -> Khả thi | D18: Kịch bản chuẩn; hoa hồng BH & NH theo giả định
A19: Lạc quan - Vượt kế hoạch (125% DT) | B19: {=NPV('1. Giả định & Thông số'!B17,'2. Báo cáo Ngân lưu'!C59:I59)*1.25+'2. Báo cáo Ngân lưu'!B54} -> 1135.0394 | C19: =IF(B19>0,"Khả thi","Không khả thi") -> Khả thi | D19: Quan hệ đối tác tốt, mở rộng nhanh
A20: Tốt nhất - Bứt phá (150% DT) | B20: {=NPV('1. Giả định & Thông số'!B17,'2. Báo cáo Ngân lưu'!C59:I59)*1.5+'2. Báo cáo Ngân lưu'!B54} -> 1672.8473 | C20: =IF(B20>0,"Khả thi","Không khả thi") -> Khả thi | D20: Mô hình nhân rộng mạnh, partnership ngân hàng lớn từ năm 2
A22: C. PHÂN TÍCH ĐỘ NHẠY - NPV THEO WACC (CHI PHÍ VỐN)
A23: MỨC WACC | B23: MÔ TẢ | C23: NPV ƯỚC TÍNH (Tr.VND) | D23: Ý NGHĨA
A24: 0.1 | B24: Thấp - Lãi suất giảm / rủi ro thấp hơn | C24: {=NPV(0.1,'2. Báo cáo Ngân lưu'!C54:I54)+'2. Báo cáo Ngân lưu'!B54} -> 7351.9941 | D24: =IF(C24>0,"Khả thi","Không khả thi → review kịch bản") -> Khả thi
A25: 0.1264 | B25: Thận trọng (WACC giảm, Re=18%) | C25: {=NPV(0.1264,'2. Báo cáo Ngân lưu'!C54:I54)+'2. Báo cáo Ngân lưu'!B54} -> 5904.2325 | D25: =IF(C25>0,"Khả thi","Không khả thi → review kịch bản") -> Khả thi
A26: 0.1432 | B26: Cơ sở (WACC hiện tại = 14,32%) | C26: {=NPV(0.1432,'2. Báo cáo Ngân lưu'!C54:I54)+'2. Báo cáo Ngân lưu'!B54} -> 5109.6787 | D26: =IF(C26>0,"Khả thi","Không khả thi → review kịch bản") -> Khả thi
A27: 0.2 | B27: Cao - Rủi ro tăng / lạm phát | C27: {=NPV(0.2,'2. Báo cáo Ngân lưu'!C54:I54)+'2. Báo cáo Ngân lưu'!B54} -> 2994.2663 | D27: =IF(C27>0,"Khả thi","Không khả thi → review kịch bản") -> Khả thi
A28: 0.25 | B28: Rất cao - Giai đoạn khủng hoảng | C28: {=NPV(0.25,'2. Báo cáo Ngân lưu'!C54:I54)+'2. Báo cáo Ngân lưu'!B54} -> 1675.7217 | D28: =IF(C28>0,"Khả thi","Không khả thi → review kịch bản") -> Khả thi

Sheet 7. Lạm phát & Khấu hao
A1: PHÂN TÍCH LẠM PHÁT & KHẤU HAO - CHAMP MẠNH CHAT (Đơn vị: Triệu VND)
A2: Giai đoạn: 2026–2032 (7 năm) | Lạm phát cơ sở: 4.5%/năm | Khấu hao: Đường thẳng (Straight-line)
A4: I. GIẢ ĐỊNH LẠM PHÁT (INFLATION ASSUMPTIONS)
A5: Chỉ tiêu | B5: Đơn vị | C5: Năm 0 | D5: Năm 1 | E5: Năm 2 | F5: Năm 3 | G5: Năm 4 | H5: Năm 5 | I5: Năm 6 | J5: Năm 7
A6: Tỷ lệ lạm phát giả định (CPI VN) | B6: %/năm | C6: - | D6: 0.045 | E6: 0.045 | F6: 0.045 | G6: 0.045 | H6: 0.045 | I6: 0.045 | J6: 0.045
A7: Tỷ lệ lạm phát nhân sự (lương) | B7: %/năm | C7: - | D7: 0.07 | E7: 0.07 | F7: 0.07 | G7: 0.07 | H7: 0.07 | I7: 0.07 | J7: 0.07
A8: Tỷ lệ lạm phát chi phí vận hành | B8: %/năm | C8: - | D8: 0.04 | E8: 0.04 | F8: 0.04 | G8: 0.04 | H8: 0.04 | I8: 0.04 | J8: 0.04
A9: Tỷ lệ lạm phát chi phí công nghệ | B9: %/năm | C9: - | D9: 0.03 | E9: 0.03 | F9: 0.03 | G9: 0.03 | H9: 0.03 | I9: 0.03 | J9: 0.03
A10: → Chỉ số giá tích lũy (CPI Index, Năm 0 = 1.000)
A11: Chỉ tiêu | B11: Đơn vị | C11: Năm 0 | D11: Năm 1 | E11: Năm 2 | F11: Năm 3 | G11: Năm 4 | H11: Năm 5 | I11: Năm 6 | J11: Năm 7
A12: Chỉ số giá CPI (cơ sở) | B12: Lần | C12: 1 | D12: =C12*(1+$D$6) -> 1.045 | E12: =D12*(1+$D$6) -> 1.092025 | F12: =E12*(1+$D$6) -> 1.1411661 | G12: =F12*(1+$D$6) -> 1.1925186 | H12: =G12*(1+$D$6) -> 1.2461819 | I12: =H12*(1+$D$6) -> 1.3022601 | J12: =I12*(1+$D$6) -> 1.3608618
A13: Chỉ số lương nhân sự | B13: Lần | C13: 1 | D13: =C13*(1+$D$7) -> 1.07 | E13: =D13*(1+$D$7) -> 1.1449 | F13: =E13*(1+$D$7) -> 1.225043 | G13: =F13*(1+$D$7) -> 1.310796 | H13: =G13*(1+$D$7) -> 1.4025517 | I13: =H13*(1+$D$7) -> 1.5007304 | J13: =I13*(1+$D$7) -> 1.6057815
A14: Chỉ số chi phí vận hành | B14: Lần | C14: 1 | D14: =C14*(1+$D$8) -> 1.04 | E14: =D14*(1+$D$8) -> 1.0816 | F14: =E14*(1+$D$8) -> 1.124864 | G14: =F14*(1+$D$8) -> 1.1698586 | H14: =G14*(1+$D$8) -> 1.2166529 | I14: =H14*(1+$D$8) -> 1.265319 | J14: =I14*(1+$D$8) -> 1.3159318
A15: Chỉ số chi phí công nghệ | B15: Lần | C15: 1 | D15: =C15*(1+$D$9) -> 1.03 | E15: =D15*(1+$D$9) -> 1.0609 | F15: =E15*(1+$D$9) -> 1.092727 | G15: =F15*(1+$D$9) -> 1.1255088 | H15: =G15*(1+$D$9) -> 1.1592741 | I15: =H15*(1+$D$9) -> 1.1940523 | J15: =I15*(1+$D$9) -> 1.2298739
A17: II. DOANH THU & CHI PHÍ ĐIỀU CHỈNH THEO LẠM PHÁT (Triệu VND - Giá thực tế)
A18: Chỉ tiêu | B18: Đơn vị | C18: Năm 0 | D18: Năm 1 | E18: Năm 2 | F18: Năm 3 | G18: Năm 4 | H18: Năm 5 | I18: Năm 6 | J18: Năm 7
A19: Doanh thu danh nghĩa (Nominal - giá gốc) | B19: Tr.VND | C19: - | D19: ='2. Báo cáo Ngân lưu'!C15 -> 592 | E19: ='2. Báo cáo Ngân lưu'!D15 -> 1402.56 | F19: ='2. Báo cáo Ngân lưu'!E15 -> 2923.2 | G19: ='2. Báo cáo Ngân lưu'!F15 -> 5448 | H19: ='2. Báo cáo Ngân lưu'!G15 -> 9920 | I19: ='2. Báo cáo Ngân lưu'!H15 -> 18292 | J19: ='2. Báo cáo Ngân lưu'!I15 -> 28072
A20: Doanh thu thực tế (Real - điều chỉnh CPI) | B20: Tr.VND | D20: =D19/D12 -> 566.50718 | E20: =E19/E12 -> 1284.3662 | F20: =F19/F12 -> 2561.5902 | G20: =G19/G12 -> 4568.4822 | H20: =H19/H12 -> 7960.3144 | I20: =I19/I12 -> 14046.349 | J20: =J19/J12 -> 20628.104
A21: Tăng trưởng DT thực tế (%) | B21: % | E21: =E20/D20-1 -> 1.2671667 | F21: =F20/E20-1 -> 0.99443915 | G21: =G20/F20-1 -> 0.7834555 | H21: =H20/G20-1 -> 0.74244181 | I21: =I20/H20-1 -> 0.764547 | J21: =J20/I20-1 -> 0.46857413
A22: Chi phí vận hành danh nghĩa (Nominal) | B22: Tr.VND | C22: - | D22: ='3. Chi phí chi tiết'!C27 -> 1489.04 | E22: ='3. Chi phí chi tiết'!D27 -> 1887.9472 | F22: ='3. Chi phí chi tiết'!E27 -> 2809.054 | G22: ='3. Chi phí chi tiết'!F27 -> 4232.74 | H22: ='3. Chi phí chi tiết'!G27 -> 6058.2455 | I22: ='3. Chi phí chi tiết'!H27 -> 9537.2384 | J22: ='3. Chi phí chi tiết'!I27 -> 13266.798
A23: Chi phí vận hành thực tế (Real - điều chỉnh CPI) | B23: Tr.VND | D23: =D22/D13 -> 1391.6262 | E23: =E22/E13 -> 1649.0062 | F23: =F22/F13 -> 2293.0248 | G23: =G22/G13 -> 3229.1371 | H23: =H22/H13 -> 4319.4453 | I23: =I22/I13 -> 6355.0646 | J23: =J22/J13 -> 8261.8952
A24: Lợi nhuận ròng thực tế (Real NI) | B24: Tr.VND | D24: =D20-D23 -> -825.11899 | E24: =E20-E23 -> -364.64 | F24: =F20-F23 -> 268.56542 | G24: =G20-G23 -> 1339.3451 | H24: =H20-H23 -> 3640.8691 | I24: =I20-I23 -> 7691.2842 | J24: =J20-J23 -> 12366.209
A27: III. LỊCH KHẤU HAO TÀI SẢN CỐ ĐỊNH (DEPRECIATION SCHEDULE)
A28: Chỉ tiêu | B28: Đơn vị | C28: Năm 0 | D28: Năm 1 | E28: Năm 2 | F28: Năm 3 | G28: Năm 4 | H28: Năm 5 | I28: Năm 6 | J28: Năm 7
A29: → A. Thông số tài sản (Giả định khấu hao đường thẳng)
A30: Tài sản | B30: Nguyên giá (Tr.VND) | C30: Thời hạn KH (năm) | D30: Giá trị còn lại (Tr.VND) | E30: KH/Năm (Tr.VND)
A31: Chi phí phát triển ứng dụng (vốn hóa) | B31: ='1. Giả định & Thông số'!$B$5 -> 1800 | C31: 7 | D31: 0 | E31: =B31/C31 -> 257.14286
A32: Chi phí vật tư & thiết bị (PC, Laptop…) | B32: ='1. Giả định & Thông số'!$B$6 -> 180 | C32: 7 | D32: 0 | E32: =B32/C32 -> 25.714286
A33: Chi phí ra mắt & triển khai sản phẩm | B33: ='1. Giả định & Thông số'!$B$7 -> 600 | C33: 3 | D33: 0 | E33: =B33/C33 -> 200
A34: Chi phí thành lập doanh nghiệp | B34: ='1. Giả định & Thông số'!$B$4 -> 10 | C34: 1 | D34: 0 | E34: =B34/C34 -> 10
A35: TỔNG NGUYÊN GIÁ TÀI SẢN | B35: =SUM(B31:B34) -> 2590 | C35: - | D35: =SUM(D31:D34) -> 0 | E35: =SUM(E31:E34) -> 492.85714
A37: → B. Lịch khấu hao theo năm (Đường thẳng - Straight Line)
A38: Chỉ tiêu | B38: Đơn vị | C38: Năm 0 | D38: Năm 1 | E38: Năm 2 | F38: Năm 3 | G38: Năm 4 | H38: Năm 5 | I38: Năm 6 | J38: Năm 7
A39: KH - Phát triển ứng dụng | B39: - | C39: - | D39: =E31 -> 257.14286 | E39: =E31 -> 257.14286 | F39: =E31 -> 257.14286 | G39: =E31 -> 257.14286 | H39: =E31 -> 257.14286 | I39: =E31 -> 257.14286 | J39: =E31 -> 257.14286
A40: KH - Vật tư & thiết bị | B40: - | C40: - | D40: =E32 -> 25.714286 | E40: =E32 -> 25.714286 | F40: =E32 -> 25.714286 | G40: =E32 -> 25.714286 | H40: =E32 -> 25.714286 | I40: =E32 -> 25.714286 | J40: =E32 -> 25.714286
A41: KH - Ra mắt & triển khai SP | B41: - | C41: - | D41: =E33 -> 200 | E41: =E33 -> 200 | F41: =E33 -> 200 | G41: - | H41: - | I41: - | J41: -
A42: KH - Chi phí thành lập DN | B42: - | C42: - | D42: =E34 -> 10 | E42: - | F42: - | G42: - | H42: - | I42: - | J42: -
A43: TỔNG KHẤU HAO HÀNG NĂM | B43: Tr.VND | C43: - | D43: =SUM(D39:D42) -> 492.85714 | E43: =SUM(E39:E42) -> 482.85714 | F43: =SUM(F39:F42) -> 482.85714 | G43: =SUM(G39:G42) -> 282.85714 | H43: =SUM(H39:H42) -> 282.85714 | I43: =SUM(I39:I42) -> 282.85714 | J43: =SUM(J39:J42) -> 282.85714
A44: Khấu hao lũy kế | B44: Tr.VND | C44: - | D44: =D43 -> 492.85714 | E44: =D44+E43 -> 975.71429 | F44: =E44+F43 -> 1458.5714 | G44: =F44+G43 -> 1741.4286 | H44: =G44+H43 -> 2024.2857 | I44: =H44+I43 -> 2307.1429 | J44: =I44+J43 -> 2590
A45: Giá trị còn lại (Net Book Value) | B45: Tr.VND | C45: =$B$35 -> 2590 | D45: =$B$35-D44 -> 2097.1429 | E45: =$B$35-E44 -> 1614.2857 | F45: =$B$35-F44 -> 1131.4286 | G45: =$B$35-G44 -> 848.57143 | H45: =$B$35-H44 -> 565.71429 | I45: =$B$35-I44 -> 282.85714 | J45: =$B$35-J44 -> 0
...
